Workbook

Sheet ranap
A1: Cluster Code | B1: Cluster Description | C1: PD | D1: acasc
C2: PDC P17AA Pancreas, Liver Resection & Shunt Proc.
C3: 50.22 | D3: Partial hepatectomy
C4: 50.3 | D4: Lobectomy of liver
C5: 50.4 | D5: Total hepatectomy
C6: 50.51 | D6: Auxiliary liver transplant
C7: 50.59 | D7: Other transplant of liver
C8: 50.61 | D8: Closure of laceration of liver
C9: 50.69 | D9: Other repair of liver
C10: 50.93 | D10: Localized perfusion of liver
C11: 52.3 | D11: Marsupialization of pancreatic cyst
C12: 52.4 | D12: Internal drainage of pancreatic cyst
C13: 52.51 | D13: Proximal pancreatectomy
C14: 52.52 | D14: Distal pancreatectomy
... C26: 52.92 | D26: Cannulation of pancreatic duct
C27: PDC P17AB Biliary Tract Proc.
C28: 51.01 | D28: Percutaneous aspiration of gallbladder
C29: 51.31 | D29: Anastomosis of gallbladder to hepatic ducts
C30: 51.32 | D30: Anastomosis of gallbladder to intestine
C31: 51.33 | D31: Anastomosis of gallbladder to pancreas
C32: 51.34 | D32: Anastomosis of gallbladder to stomach
C33: 51.35 | D33: Other gallbladder anastomosis
C34: 51.36 | D34: Choledochoenterostomy
C35: 51.37 | D35: Anastomosis of hepatic duct to gastrointestinal tract
C36: 51.39 | D36: Other bile duct anastomosis
C37: 51.41 | D37: Common duct exploration for removal of calculus
C38: 51.42 | D38: Common duct exploration for relief of other obstruction
C39: 51.43 | D39: Insertion of choledochohepatic tube for decompression
... C55: 51.98 | D55: Other percutaneous procedures on biliary tract
C56: PDC P17AC Pancreas & Liver Proc. except Resection
C57: 17.63 | D57: Laser interstitial thermal therapy [LITT] of lesion or tissue of liver under guidance
C58: 50.14 | D58: Laparoscopic liver biopsy
C59: 50.21 | D59: Marsupialization of lesion of liver
C60: 50.23 | D60: Open ablation of liver lesion or tissue
C61: 50.24 | D61: Percutaneous ablation of liver lesion or tissue
C62: 50.25 | D62: Laparoscopic ablation of liver lesion or tissue
C63: 50.26 | D63: Other and unspecified ablation of liver lesion or tissue
C64: 50.29 | D64: Other destruction of lesion of liver
C65: 51.02 | D65: Trocar cholecystostomy
C66: 51.03 | D66: Other cholecystostomy
...

Sheet rajal cluster icd10_web20260922
A1: Cluster Type | B1: Cluster Code | C1: Cluster Description | D1: ICD-10 Code | E1: ICD-10-Description
A2: PDC | B2: D17AA | C2: Chirosis And Alcholic Hepatitis | D2: ="K70.0" -> K70.0 | E2: Alcoholic fatty liver
A3: PDC | B3: D17AA | C3: Chirosis And Alcholic Hepatitis | D3: ="K70.1" -> K70.1 | E3: Alcoholic hepatitis
A4: PDC | B4: D17AA | C4: Chirosis And Alcholic Hepatitis | D4: ="K70.2" -> K70.2 | E4: Alcoholic fibrosis and sclerosis of liver
A5: PDC | B5: D17AA | C5: Chirosis And Alcholic Hepatitis | D5: ="K70.3" -> K70.3 | E5: Alcoholic cirrhosis of liver
A6: PDC | B6: D17AA | C6: Chirosis And Alcholic Hepatitis | D6: ="K70.4" -> K70.4 | E6: Alcoholic hepatic failure
A7: PDC | B7: D17AA | C7: Chirosis And Alcholic Hepatitis | D7: ="K70.9" -> K70.9 | E7: Alcoholic liver disease, unspecified
A8: PDC | B8: D17AA | C8: Chirosis And Alcholic Hepatitis | D8: ="K72.0" -> K72.0 | E8: Acute and subacute hepatic failure
A9: PDC | B9: D17AA | C9: Chirosis And Alcholic Hepatitis | D9: ="K72.1" -> K72.1 | E9: Chronic hepatic failure
A10: PDC | B10: D17AA | C10: Chirosis And Alcholic Hepatitis | D10: ="K72.9" -> K72.9 | E10: Hepatic failure, unspecified
A11: PDC | B11: D17AA | C11: Chirosis And Alcholic Hepatitis | D11: ="K74.0" -> K74.0 | E11: Hepatic fibrosis
A12: PDC | B12: D17AA | C12: Chirosis And Alcholic Hepatitis | D12: ="K74.1" -> K74.1 | E12: Hepatic sclerosis
A13: PDC | B13: D17AA | C13: Chirosis And Alcholic Hepatitis | D13: ="K74.2" -> K74.2 | E13: Hepatic fibrosis with hepatic sclerosis
A14: PDC | B14: D17AA | C14: Chirosis And Alcholic Hepatitis | D14: ="K74.3" -> K74.3 | E14: Primary biliary cirrhosis
A15: PDC | B15: D17AA | C15: Chirosis And Alcholic Hepatitis | D15: ="K74.4" -> K74.4 | E15: Secondary biliary cirrhosis
A16: PDC | B16: D17AA | C16: Chirosis And Alcholic Hepatitis | D16: ="K74.5" -> K74.5 | E16: Biliary cirrhosis, unspecified
A17: PDC | B17: D17AA | C17: Chirosis And Alcholic Hepatitis | D17: ="K74.6" -> K74.6 | E17: Other and unspecified cirrhosis of liver
A18: PDC | B18: D17AA | C18: Chirosis And Alcholic Hepatitis | D18: ="K76.6" -> K76.6 | E18: Portal hypertension
A19: PDC | B19: D17AA | C19: Chirosis And Alcholic Hepatitis | D19: ="K76.7" -> K76.7 | E19: Hepatorenal syndrome
A20: PDC | B20: D17AB | C20: Malignancy Of Hepatobiliary Or Pancreas | D20: ="C22.0" -> C22.0 | E20: Malignant neoplasm, liver cell carcinoma
A21: PDC | B21: D17AB | C21: Malignancy Of Hepatobiliary Or Pancreas | D21: ="C22.1" -> C22.1 | E21: Malignant neoplasm, intrahepatic bile duct carcinoma
A22: PDC | B22: D17AB | C22: Malignancy Of Hepatobiliary Or Pancreas | D22: ="C22.2" -> C22.2 | E22: Malignant neoplasm, hepatoblastoma
A23: PDC | B23: D17AB | C23: Malignancy Of Hepatobiliary Or Pancreas | D23: ="C22.3" -> C22.3 | E23: Malignant neoplasm, angiosarcoma of liver
A24: PDC | B24: D17AB | C24: Malignancy Of Hepatobiliary Or Pancreas | D24: ="C22.4" -> C22.4 | E24: Malignant neoplasm, other sarcomas of liver
A25: PDC | B25: D17AB | C25: Malignancy Of Hepatobiliary Or Pancreas | D25: ="C22.7" -> C22.7 | E25: Malignant neoplasm, other specified carcinomas of liver
A26: PDC | B26: D17AB | C26: Malignancy Of Hepatobiliary Or Pancreas | D26: ="C22.9" -> C22.9 | E26: Malignant neoplasm, liver, unspecified
A27: PDC | B27: D17AB | C27: Malignancy Of Hepatobiliary Or Pancreas | D27: ="C23" -> C23 | E27: Malignant neoplasm of gallbladder
A28: PDC | B28: D17AB | C28: Malignancy Of Hepatobiliary Or Pancreas | D28: ="C24.0" -> C24.0 | E28: Malignant neoplasm, extrahepatic bile duct
A29: PDC | B29: D17AB | C29: Malignancy Of Hepatobiliary Or Pancreas | D29: ="C24.1" -> C24.1 | E29: Malignant neoplasm, ampulla of vater
A30: PDC | B30: D17AB | C30: Malignancy Of Hepatobiliary Or Pancreas | D30: ="C24.8" -> C24.8 | E30: Malignant neoplasm, overlapping lesion of biliary tract
A31: PDC | B31: D17AB | C31: Malignancy Of Hepatobiliary Or Pancreas | D31: ="C24.9" -> C24.9 | E31: Malignant neoplasm, biliary tract, unspecified
A32: PDC | B32: D17AB | C32: Malignancy Of Hepatobiliary Or Pancreas | D32: ="C25.0" -> C25.0 | E32: Malignant neoplasm, head of pancreas
A33: PDC | B33: D17AB | C33: Malignancy Of Hepatobiliary Or Pancreas | D33: ="C25.1" -> C25.1 | E33: Malignant neoplasm, body of pancreas
A34: PDC | B34: D17AB | C34: Malignancy Of Hepatobiliary Or Pancreas | D34: ="C25.2" -> C25.2 | E34: Malignant neoplasm, tail of pancreas
A35: PDC | B35: D17AB | C35: Malignancy Of Hepatobiliary Or Pancreas | D35: ="C25.3" -> C25.3 | E35: Malignant neoplasm, pancreatic duct
A36: PDC | B36: D17AB | C36: Malignancy Of Hepatobiliary Or Pancreas | D36: ="C25.4" -> C25.4 | E36: Malignant neoplasm, endocrine pancreas
A37: PDC | B37: D17AB | C37: Malignancy Of Hepatobiliary Or Pancreas | D37: ="C25.7" -> C25.7 | E37: Malignant neoplasm, other parts of pancreas
A38: PDC | B38: D17AB | C38: Malignancy Of Hepatobiliary Or Pancreas | D38: ="C25.8" -> C25.8 | E38: Malignant neoplasm, overlapping lesion of pancreas
A39: PDC | B39: D17AB | C39: Malignancy Of Hepatobiliary Or Pancreas | D39: ="C25.9" -> C25.9 | E39: Malignant neoplasm, pancreas, unspecified
A40: PDC | B40: D17AB | C40: Malignancy Of Hepatobiliary Or Pancreas | D40: ="C78.7" -> C78.7 | E40: Secondary malignant neoplasm of liver
...

Sheet rajal cluster icd9cm_web2026092
A1: Cluster Type | B1: Cluster Code | C1: Cluster Description | D1: ICD-9-CM Code | E1: ICD-9-CM Description
A2: PDC | B2: P17KL | C2: ERCP Diagnostic | D2: ="51.10" -> 51.10 | E2: Endoscopic retrograde cholangiopancreatography [ERCP]
A3: PDC | B3: P17KL | C3: ERCP Diagnostic | D3: ="51.11" -> 51.11 | E3: Endoscopic retrograde cholangiography [ERC]
A4: PDC | B4: P17KL | C4: ERCP Diagnostic | D4: ="51.14" -> 51.14 | E4: Other closed [endoscopic] biopsy of biliary duct or sphincter of Oddi
A5: PDC | B5: P17KL | C5: ERCP Diagnostic | D5: ="51.15" -> 51.15 | E5: Pressure measurement of sphincter of Oddi
A6: PDC | B6: P17KL | C6: ERCP Diagnostic | D6: ="52.13" -> 52.13 | E6: Endoscopic retrograde pancreatography [ERP]
A7: PDC | B7: P17KJ | C7: Other Hepatobiliary Major Proc. | D7: ="50.11" -> 50.11 | E7: Closed (percutaneous) [needle] biopsy of liver
A8: PDC | B8: P17KJ | C8: Other Hepatobiliary Major Proc. | D8: ="50.19" -> 50.19 | E8: Other diagnostic procedures on liver
A9: PDC | B9: P17KJ | C9: Other Hepatobiliary Major Proc. | D9: ="50.91" -> 50.91 | E9: Percutaneous aspiration of liver
A10: PDC | B10: P17KJ | C10: Other Hepatobiliary Major Proc. | D10: ="50.93" -> 50.93 | E10: Localized perfusion of liver
A11: PDC | B11: P17KJ | C11: Other Hepatobiliary Major Proc. | D11: ="50.94" -> 50.94 | E11: Other injection of therapeutic substance into liver
A12: PDC | B12: P17KJ | C12: Other Hepatobiliary Major Proc. | D12: ="51.01" -> 51.01 | E12: Percutaneous aspiration of gallbladder
A13: PDC | B13: P17KJ | C13: Other Hepatobiliary Major Proc. | D13: ="51.12" -> 51.12 | E13: Percutaneous biopsy of gallbladder or bile ducts
A14: PDC | B14: P17KJ | C14: Other Hepatobiliary Major Proc. | D14: ="51.19" -> 51.19 | E14: Other diagnostic procedures on biliary tract
A15: PDC | B15: P17KJ | C15: Other Hepatobiliary Major Proc. | D15: ="51.96" -> 51.96 | E15: Percutaneous extraction of common duct stones
A16: PDC | B16: P17KJ | C16: Other Hepatobiliary Major Proc. | D16: ="51.98" -> 51.98 | E16: Other percutaneous procedures on biliary tract
A17: PDC | B17: P17KJ | C17: Other Hepatobiliary Major Proc. | D17: ="52.11" -> 52.11 | E17: Closed [aspiration] [needle] [percutaneous] biopsy of pancreas
A18: PDC | B18: P17KJ | C18: Other Hepatobiliary Major Proc. | D18: ="52.14" -> 52.14 | E18: Closed [endoscopic] biopsy of pancreatic duct
A19: PDC | B19: P17KJ | C19: Other Hepatobiliary Major Proc. | D19: ="52.19" -> 52.19 | E19: Other diagnostic procedures on pancreas
A20: PDC | B20: P17KJ | C20: Other Hepatobiliary Major Proc. | D20: ="54.24" -> 54.24 | E20: Closed [percutaneous] [needle] biopsy of intra-abdominal mass
A21: PDC | B21: P17KJ | C21: Other Hepatobiliary Major Proc. | D21: ="87.53" -> 87.53 | E21: Intraoperative cholangiogram
A22: PDC | B22: P17KH | C22: Other Hepatobiliary Minor Proc. | D22: ="50.99" -> 50.99 | E22: Other operations on liver
A23: PDC | B23: P17KH | C23: Other Hepatobiliary Minor Proc. | D23: ="96.41" -> 96.41 | E23: Irrigation of cholecystostomy and other biliary tube
A24: PDC | B24: P17KH | C24: Other Hepatobiliary Minor Proc. | D24: ="96.42" -> 96.42 | E24: Irrigation of pancreatic tube
A25: PDC | B25: P17KH | C25: Other Hepatobiliary Minor Proc. | D25: ="97.54" -> 97.54 | E25: Removal of cholecystostomy tube
A26: PDC | B26: P17KH | C26: Other Hepatobiliary Minor Proc. | D26: ="97.55" -> 97.55 | E26: Removal of t-tube, other bile duct tube, or liver tube
A27: PDC | B27: P17KH | C27: Other Hepatobiliary Minor Proc. | D27: ="97.56" -> 97.56 | E27: Removal of pancreatic tube or drain
A28: AX | B28: 17PBX | C28: Laparoscopic Procedures | D28: ="50.40" -> 50.40 | E28: Laparoscopic liver resection (IM)
A29: AX | B29: 17PBX | C29: Laparoscopic Procedures | D29: ="52.50" -> 52.50 | E29: Laparoscopic partial pancreatectomy (IM)
A30: AX | B30: 17PBX | C30: Laparoscopic Procedures | D30: ="52.60" -> 52.60 | E30: Laparoscopic total pancreatectomy (IM)
A31: AX | B31: 17PBX | C31: Laparoscopic Procedures | D31: ="52.70" -> 52.70 | E31: Laparoscopic pancreaticoduodenectomy (IM)
A32: AX | B32: 17PCX | C32: Closed Common Duct Exploration Procedures | D32: ="51.10" -> 51.10 | E32: Endoscopic retrograde cholangiopancreatography [ERCP]
A33: AX | B33: 17PCX | C33: Closed Common Duct Exploration Procedures | D33: ="51.11" -> 51.11 | E33: Endoscopic retrograde cholangiography [ERC]
A34: AX | B34: 17PCX | C34: Closed Common Duct Exploration Procedures | D34: ="51.14" -> 51.14 | E34: Other closed [endoscopic] biopsy of biliary duct or sphincter of Oddi
A35: AX | B35: 17PCX | C35: Closed Common Duct Exploration Procedures | D35: ="51.15" -> 51.15 | E35: Pressure measurement of sphincter of Oddi
A36: AX | B36: 17PCX | C36: Closed Common Duct Exploration Procedures | D36: ="51.64" -> 51.64 | E36: Endoscopic excision or destruction of lesion of biliary ducts or sphincter of Oddi
A37: AX | B37: 17PCX | C37: Closed Common Duct Exploration Procedures | D37: ="51.84" -> 51.84 | E37: Endoscopic dilation of ampulla and biliary duct
A38: AX | B38: 17PCX | C38: Closed Common Duct Exploration Procedures | D38: ="51.85" -> 51.85 | E38: Endoscopic sphincterotomy and papillotomy
A39: AX | B39: 17PCX | C39: Closed Common Duct Exploration Procedures | D39: ="51.86" -> 51.86 | E39: Endoscopic insertion of nasobiliary drainage tube
A40: AX | B40: 17PCX | C40: Closed Common Duct Exploration Procedures | D40: ="51.87" -> 51.87 | E40: Endoscopic insertion of stent (tube) into bile duct
...

Sheet ranap cluster icd9cm_web2026092
A1: Cluster Type | B1: Cluster Code | C1: Cluster Description | D1: ICD-9-CM Code | E1: ICD-9-CM Description
A2: PDC | B2: P17AA | C2: Pancreas, Liver Resection & Shunt Proc. | D2: ="50.22" -> 50.22 | E2: Partial hepatectomy
A3: PDC | B3: P17AA | C3: Pancreas, Liver Resection & Shunt Proc. | D3: ="50.3" -> 50.3 | E3: Lobectomy of liver
A4: PDC | B4: P17AA | C4: Pancreas, Liver Resection & Shunt Proc. | D4: ="50.4" -> 50.4 | E4: Total hepatectomy
A5: PDC | B5: P17AA | C5: Pancreas, Liver Resection & Shunt Proc. | D5: ="50.51" -> 50.51 | E5: Auxiliary liver transplant
A6: PDC | B6: P17AA | C6: Pancreas, Liver Resection & Shunt Proc. | D6: ="50.59" -> 50.59 | E6: Other transplant of liver
A7: PDC | B7: P17AA | C7: Pancreas, Liver Resection & Shunt Proc. | D7: ="50.61" -> 50.61 | E7: Closure of laceration of liver
A8: PDC | B8: P17AA | C8: Pancreas, Liver Resection & Shunt Proc. | D8: ="50.69" -> 50.69 | E8: Other repair of liver
A9: PDC | B9: P17AA | C9: Pancreas, Liver Resection & Shunt Proc. | D9: ="50.93" -> 50.93 | E9: Localized perfusion of liver
A10: PDC | B10: P17AA | C10: Pancreas, Liver Resection & Shunt Proc. | D10: ="52.3" -> 52.3 | E10: Marsupialization of pancreatic cyst
A11: PDC | B11: P17AA | C11: Pancreas, Liver Resection & Shunt Proc. | D11: ="52.4" -> 52.4 | E11: Internal drainage of pancreatic cyst
A12: PDC | B12: P17AA | C12: Pancreas, Liver Resection & Shunt Proc. | D12: ="52.51" -> 52.51 | E12: Proximal pancreatectomy
A13: PDC | B13: P17AA | C13: Pancreas, Liver Resection & Shunt Proc. | D13: ="52.52" -> 52.52 | E13: Distal pancreatectomy
A14: PDC | B14: P17AA | C14: Pancreas, Liver Resection & Shunt Proc. | D14: ="52.53" -> 52.53 | E14: Radical subtotal pancreatectomy
A15: PDC | B15: P17AA | C15: Pancreas, Liver Resection & Shunt Proc. | D15: ="52.59" -> 52.59 | E15: Other partial pancreatectomy
A16: PDC | B16: P17AA | C16: Pancreas, Liver Resection & Shunt Proc. | D16: ="52.6" -> 52.6 | E16: Total pancreatectomy
A17: PDC | B17: P17AA | C17: Pancreas, Liver Resection & Shunt Proc. | D17: ="52.7" -> 52.7 | E17: Radical pancreaticoduodenectomy
A18: PDC | B18: P17AA | C18: Pancreas, Liver Resection & Shunt Proc. | D18: ="52.80" -> 52.80 | E18: Pancreatic transplant, not otherwise specified
A19: PDC | B19: P17AA | C19: Pancreas, Liver Resection & Shunt Proc. | D19: ="52.81" -> 52.81 | E19: Reimplantation of pancreatic tissue
A20: PDC | B20: P17AA | C20: Pancreas, Liver Resection & Shunt Proc. | D20: ="52.82" -> 52.82 | E20: Homotransplant of pancreas
A21: PDC | B21: P17AA | C21: Pancreas, Liver Resection & Shunt Proc. | D21: ="52.83" -> 52.83 | E21: Heterotransplant of pancreas
A22: PDC | B22: P17AA | C22: Pancreas, Liver Resection & Shunt Proc. | D22: ="52.84" -> 52.84 | E22: Autotransplantation of cells of Islets of Langerhans
A23: PDC | B23: P17AA | C23: Pancreas, Liver Resection & Shunt Proc. | D23: ="52.85" -> 52.85 | E23: Allotransplantation of cells of Islets of Langerhans
A24: PDC | B24: P17AA | C24: Pancreas, Liver Resection & Shunt Proc. | D24: ="52.86" -> 52.86 | E24: Transplantation of cells of Islets of Langerhans, not otherwise specified
A25: PDC | B25: P17AA | C25: Pancreas, Liver Resection & Shunt Proc. | D25: ="52.92" -> 52.92 | E25: Cannulation of pancreatic duct
A26: PDC | B26: P17AB | C26: Biliary Tract Proc. | D26: ="51.01" -> 51.01 | E26: Percutaneous aspiration of gallbladder
A27: PDC | B27: P17AB | C27: Biliary Tract Proc. | D27: ="51.31" -> 51.31 | E27: Anastomosis of gallbladder to hepatic ducts
A28: PDC | B28: P17AB | C28: Biliary Tract Proc. | D28: ="51.32" -> 51.32 | E28: Anastomosis of gallbladder to intestine
A29: PDC | B29: P17AB | C29: Biliary Tract Proc. | D29: ="51.33" -> 51.33 | E29: Anastomosis of gallbladder to pancreas
A30: PDC | B30: P17AB | C30: Biliary Tract Proc. | D30: ="51.34" -> 51.34 | E30: Anastomosis of gallbladder to stomach
A31: PDC | B31: P17AB | C31: Biliary Tract Proc. | D31: ="51.35" -> 51.35 | E31: Other gallbladder anastomosis
A32: PDC | B32: P17AB | C32: Biliary Tract Proc. | D32: ="51.36" -> 51.36 | E32: Choledochoenterostomy
A33: PDC | B33: P17AB | C33: Biliary Tract Proc. | D33: ="51.37" -> 51.37 | E33: Anastomosis of hepatic duct to gastrointestinal tract
A34: PDC | B34: P17AB | C34: Biliary Tract Proc. | D34: ="51.39" -> 51.39 | E34: Other bile duct anastomosis
A35: PDC | B35: P17AB | C35: Biliary Tract Proc. | D35: ="51.41" -> 51.41 | E35: Common duct exploration for removal of calculus
A36: PDC | B36: P17AB | C36: Biliary Tract Proc. | D36: ="51.42" -> 51.42 | E36: Common duct exploration for relief of other obstruction
A37: PDC | B37: P17AB | C37: Biliary Tract Proc. | D37: ="51.43" -> 51.43 | E37: Insertion of choledochohepatic tube for decompression
A38: PDC | B38: P17AB | C38: Biliary Tract Proc. | D38: ="51.49" -> 51.49 | E38: Incision of other bile ducts for relief of obstruction
A39: PDC | B39: P17AB | C39: Biliary Tract Proc. | D39: ="51.51" -> 51.51 | E39: Exploration of common duct
A40: PDC | B40: P17AB | C40: Biliary Tract Proc. | D40: ="51.59" -> 51.59 | E40: Other incision of other bile duct
...

Sheet ranap cluster icd10_web20260922
A1: Cluster Type | B1: Cluster Code | C1: Cluster Description | D1: ICD-10 Code | E1: ICD-10 Description
A2: PDC | B2: D17AA | C2: Chirosis And Alcholic Hepatitis | D2: ="K70.0" -> K70.0 | E2: Alcoholic fatty liver
A3: PDC | B3: D17AA | C3: Chirosis And Alcholic Hepatitis | D3: ="K70.1" -> K70.1 | E3: Alcoholic hepatitis
A4: PDC | B4: D17AA | C4: Chirosis And Alcholic Hepatitis | D4: ="K70.2" -> K70.2 | E4: Alcoholic fibrosis and sclerosis of liver
A5: PDC | B5: D17AA | C5: Chirosis And Alcholic Hepatitis | D5: ="K70.3" -> K70.3 | E5: Alcoholic cirrhosis of liver
A6: PDC | B6: D17AA | C6: Chirosis And Alcholic Hepatitis | D6: ="K70.4" -> K70.4 | E6: Alcoholic hepatic failure
A7: PDC | B7: D17AA | C7: Chirosis And Alcholic Hepatitis | D7: ="K70.9" -> K70.9 | E7: Alcoholic liver disease, unspecified
A8: PDC | B8: D17AA | C8: Chirosis And Alcholic Hepatitis | D8: ="K72.0" -> K72.0 | E8: Acute and subacute hepatic failure
A9: PDC | B9: D17AA | C9: Chirosis And Alcholic Hepatitis | D9: ="K72.1" -> K72.1 | E9: Chronic hepatic failure
A10: PDC | B10: D17AA | C10: Chirosis And Alcholic Hepatitis | D10: ="K72.9" -> K72.9 | E10: Hepatic failure, unspecified
A11: PDC | B11: D17AA | C11: Chirosis And Alcholic Hepatitis | D11: ="K74.0" -> K74.0 | E11: Hepatic fibrosis
A12: PDC | B12: D17AA | C12: Chirosis And Alcholic Hepatitis | D12: ="K74.1" -> K74.1 | E12: Hepatic sclerosis
A13: PDC | B13: D17AA | C13: Chirosis And Alcholic Hepatitis | D13: ="K74.2" -> K74.2 | E13: Hepatic fibrosis with hepatic sclerosis
A14: PDC | B14: D17AA | C14: Chirosis And Alcholic Hepatitis | D14: ="K74.3" -> K74.3 | E14: Primary biliary cirrhosis
A15: PDC | B15: D17AA | C15: Chirosis And Alcholic Hepatitis | D15: ="K74.4" -> K74.4 | E15: Secondary biliary cirrhosis
A16: PDC | B16: D17AA | C16: Chirosis And Alcholic Hepatitis | D16: ="K74.5" -> K74.5 | E16: Biliary cirrhosis, unspecified
A17: PDC | B17: D17AA | C17: Chirosis And Alcholic Hepatitis | D17: ="K74.6" -> K74.6 | E17: Other and unspecified cirrhosis of liver
A18: PDC | B18: D17AA | C18: Chirosis And Alcholic Hepatitis | D18: ="K76.6" -> K76.6 | E18: Portal hypertension
A19: PDC | B19: D17AA | C19: Chirosis And Alcholic Hepatitis | D19: ="K76.7" -> K76.7 | E19: Hepatorenal syndrome
A20: PDC | B20: D17AB | C20: Malignancy Of Hepatobiliary Or Pancreas | D20: ="C22.0" -> C22.0 | E20: Malignant neoplasm, liver cell carcinoma
A21: PDC | B21: D17AB | C21: Malignancy Of Hepatobiliary Or Pancreas | D21: ="C22.1" -> C22.1 | E21: Malignant neoplasm, intrahepatic bile duct carcinoma
A22: PDC | B22: D17AB | C22: Malignancy Of Hepatobiliary Or Pancreas | D22: ="C22.2" -> C22.2 | E22: Malignant neoplasm, hepatoblastoma
A23: PDC | B23: D17AB | C23: Malignancy Of Hepatobiliary Or Pancreas | D23: ="C22.3" -> C22.3 | E23: Malignant neoplasm, angiosarcoma of liver
A24: PDC | B24: D17AB | C24: Malignancy Of Hepatobiliary Or Pancreas | D24: ="C22.4" -> C22.4 | E24: Malignant neoplasm, other sarcomas of liver
A25: PDC | B25: D17AB | C25: Malignancy Of Hepatobiliary Or Pancreas | D25: ="C22.7" -> C22.7 | E25: Malignant neoplasm, other specified carcinomas of liver
A26: PDC | B26: D17AB | C26: Malignancy Of Hepatobiliary Or Pancreas | D26: ="C22.9" -> C22.9 | E26: Malignant neoplasm, liver, unspecified
A27: PDC | B27: D17AB | C27: Malignancy Of Hepatobiliary Or Pancreas | D27: ="C23" -> C23 | E27: Malignant neoplasm of gallbladder
A28: PDC | B28: D17AB | C28: Malignancy Of Hepatobiliary Or Pancreas | D28: ="C24.0" -> C24.0 | E28: Malignant neoplasm, extrahepatic bile duct
A29: PDC | B29: D17AB | C29: Malignancy Of Hepatobiliary Or Pancreas | D29: ="C24.1" -> C24.1 | E29: Malignant neoplasm, ampulla of vater
A30: PDC | B30: D17AB | C30: Malignancy Of Hepatobiliary Or Pancreas | D30: ="C24.8" -> C24.8 | E30: Malignant neoplasm, overlapping lesion of biliary tract
A31: PDC | B31: D17AB | C31: Malignancy Of Hepatobiliary Or Pancreas | D31: ="C24.9" -> C24.9 | E31: Malignant neoplasm, biliary tract, unspecified
A32: PDC | B32: D17AB | C32: Malignancy Of Hepatobiliary Or Pancreas | D32: ="C25.0" -> C25.0 | E32: Malignant neoplasm, head of pancreas
A33: PDC | B33: D17AB | C33: Malignancy Of Hepatobiliary Or Pancreas | D33: ="C25.1" -> C25.1 | E33: Malignant neoplasm, body of pancreas
A34: PDC | B34: D17AB | C34: Malignancy Of Hepatobiliary Or Pancreas | D34: ="C25.2" -> C25.2 | E34: Malignant neoplasm, tail of pancreas
A35: PDC | B35: D17AB | C35: Malignancy Of Hepatobiliary Or Pancreas | D35: ="C25.3" -> C25.3 | E35: Malignant neoplasm, pancreatic duct
A36: PDC | B36: D17AB | C36: Malignancy Of Hepatobiliary Or Pancreas | D36: ="C25.4" -> C25.4 | E36: Malignant neoplasm, endocrine pancreas
A37: PDC | B37: D17AB | C37: Malignancy Of Hepatobiliary Or Pancreas | D37: ="C25.7" -> C25.7 | E37: Malignant neoplasm, other parts of pancreas
A38: PDC | B38: D17AB | C38: Malignancy Of Hepatobiliary Or Pancreas | D38: ="C25.8" -> C25.8 | E38: Malignant neoplasm, overlapping lesion of pancreas
A39: PDC | B39: D17AB | C39: Malignancy Of Hepatobiliary Or Pancreas | D39: ="C25.9" -> C25.9 | E39: Malignant neoplasm, pancreas, unspecified
A40: PDC | B40: D17AB | C40: Malignancy Of Hepatobiliary Or Pancreas | D40: ="C78.7" -> C78.7 | E40: Secondary malignant neoplasm of liver
...

Sheet rajal
A1: P15KH | B1: Peripheral Angioplasty Proc. | C1: PDC
C2: PDC P17KL ERCP Diagnostic
C3: 51.10 | D3: Endoscopic retrograde cholangiopancreatography [ERCP]
A4: P16KU | B4: Endoscopy of Upper Gastrointestinal Major Proc. | C4: PDC
C5: 51.11 | D5: Endoscopic retrograde cholangiography [ERC]
C6: 51.14 | D6: Other closed [endoscopic] biopsy of biliary duct or sphincter of Oddi
C7: 51.15 | D7: Pressure measurement of sphincter of Oddi
C8: 52.13 | D8: Endoscopic retrograde pancreatography [ERP]
C9: PDC P17KJ Other Hepatobiliary Major Proc.
C10: 50.11 | D10: Closed (percutaneous) [needle] biopsy of liver
C11: 50.19 | D11: Other diagnostic procedures on liver
C12: 50.91 | D12: Percutaneous aspiration of liver
C13: 50.93 | D13: Localized perfusion of liver
C14: 50.94 | D14: Other injection of therapeutic substance into liver
C15: 51.01 | D15: Percutaneous aspiration of gallbladder
C16: 51.12 | D16: Percutaneous biopsy of gallbladder or bile ducts
C17: 51.19 | D17: Other diagnostic procedures on biliary tract
A18: P16KT | B18: Colonoscopy Proc. | C18: PDC
C19: 51.96 | D19: Percutaneous extraction of common duct stones
C20: 51.98 | D20: Other percutaneous procedures on biliary tract
C21: 52.11 | D21: Closed [aspiration] [needle] [percutaneous] biopsy of pancreas
C22: 52.14 | D22: Closed [endoscopic] biopsy of pancreatic duct
A23: P16KX | B23: Major Biopsy for Digestive System | C23: PDC
C24: 52.19 | D24: Other diagnostic procedures on pancreas
C25: 54.24 | D25: Closed [percutaneous] [needle] biopsy of intra-abdominal mass
C26: 87.53 | D26: Intraoperative cholangiogram
C27: PDC P17KH Other Hepatobiliary Minor Proc.
C28: 50.99 | D28: Other operations on liver
A29: P16KY | B29: Moderate Biopsy for Digestive System | C29: PDC
C30: 96.41 | D30: Irrigation of cholecystostomy and other biliary tube
C31: 96.42 | D31: Irrigation of pancreatic tube
C32: 97.54 | D32: Removal of cholecystostomy tube
C33: 97.55 | D33: Removal of t-tube, other bile duct tube, or liver tube
C34: 97.56 | D34: Removal of pancreatic tube or drain
C35: 49.22 | D35: Biopsy of perianal tissue
A36: P16KV | B36: Endoscopy of Upper Gastrointestinal Minor Proc. | C36: PDC
C37: 42.22 | D37: Esophagoscopy through artificial stoma
C38: 42.23 | D38: Other esophagoscopy
C39: 44.11 | D39: Transabdominal gastroscopy
C40: 44.12 | D40: Gastroscopy through artificial stoma
...

Sheet ip op cluster
A1: Cluster Type | B1: PTD | C1: Cluster Code | D1: Cluster Description | E1: ICD9CM Code | F1: ICD9CM Description | G1: procgr | H1: New Cluster Descrirption | I1: New Cluster Code | J1: tarif iDRG | K1: tarif iDRG + AF | L1: tarif rs 2025 | M1: tarif rs uji coba | N1: Jumlah Kasus | O1: Total | P1: p25 uji coba | Q1: p50 uji coba | R1: p75 uji coba | S1: p90 uji coba | T1: Kompetensi | U1: Layanan
A2: PDC | B2: 1 | C2: P16AB | D2: Stomach, Esophagus & Duodenal Resection Procedures | E2: 41.5 | F2: Total splenectomy | G2: =VLOOKUP($E2,proc!$A:$D,3, FALSE) -> 4 | H2: =D2 -> Stomach, Esophagus & Duodenal Resection Procedures | I2: =C2 -> P16AB | J2: =VLOOKUP($C2,'tarif idrg'!$A:$O,11,FALSE) -> 18485238 | K2: =VLOOKUP($C2,'tarif idrg'!$A:$O,15,FALSE) -> 18485238 | L2: =VLOOKUP($E2,'ip prosedur-2025'!$A:$H,4,FALSE) -> 52429636 | M2: =VLOOKUP($E2,'ip prosedur-14 okt-15 juni 2026'!$A:$H,4,FALSE) -> 52865089 | N2: =VLOOKUP($E2,'ip prosedur-14 okt-15 juni 2026'!$A:$H,3, FALSE) -> 543 | O2: =M2*N2 -> 28705743414 | P2: =VLOOKUP($E2,'ip prosedur-14 okt-15 juni 2026'!$A:$H,5,FALSE) -> 24391385 | Q2: =VLOOKUP($E2,'ip prosedur-14 okt-15 juni 2026'!$A:$H,6,FALSE) -> 37323000 | R2: =VLOOKUP($E2,'ip prosedur-14 okt-15 juni 2026'!$A:$H,7,FALSE) -> 62092164 | S2: =VLOOKUP($E2,'ip prosedur-14 okt-15 juni 2026'!$A:$H,8,FALSE) -> 102438900
A3: PDC | B3: 1 | C3: P16AB | D3: Stomach, Esophagus & Duodenal Resection Procedures | E3: 42.41 | F3: Partial esophagectomy | G3: =VLOOKUP($E3,proc!$A:$D,3, FALSE) -> 6 | H3: =D3 -> Stomach, Esophagus & Duodenal Resection Procedures | I3: =C3 -> P16AB | J3: =VLOOKUP($C3,'tarif idrg'!$A:$O,11,FALSE) -> 18485238 | K3: =VLOOKUP($C3,'tarif idrg'!$A:$O,15,FALSE) -> 18485238 | L3: =VLOOKUP($E3,'ip prosedur-2025'!$A:$H,4,FALSE) -> 1.2611458e+08 | M3: =VLOOKUP($E3,'ip prosedur-14 okt-15 juni 2026'!$A:$H,4,FALSE) -> 1.1940485e+08 | N3: =VLOOKUP($E3,'ip prosedur-14 okt-15 juni 2026'!$A:$H,3, FALSE) -> 43 | O3: =M3*N3 -> 5134408520 | P3: =VLOOKUP($E3,'ip prosedur-14 okt-15 juni 2026'!$A:$H,5,FALSE) -> 53608899 | Q3: =VLOOKUP($E3,'ip prosedur-14 okt-15 juni 2026'!$A:$H,6,FALSE) -> 108589810 | R3: =VLOOKUP($E3,'ip prosedur-14 okt-15 juni 2026'!$A:$H,7,FALSE) -> 157989413 | S3: =VLOOKUP($E3,'ip prosedur-14 okt-15 juni 2026'!$A:$H,8,FALSE) -> 205202294
A4: PDC | B4: 1 | C4: P16AB | D4: Stomach, Esophagus & Duodenal Resection Procedures | E4: 42.42 | F4: Total esophagectomy | G4: =VLOOKUP($E4,proc!$A:$D,3, FALSE) -> 6 | H4: =D4 -> Stomach, Esophagus & Duodenal Resection Procedures | I4: =C4 -> P16AB | J4: =VLOOKUP($C4,'tarif idrg'!$A:$O,11,FALSE) -> 18485238 | K4: =VLOOKUP($C4,'tarif idrg'!$A:$O,15,FALSE) -> 18485238 | L4: =VLOOKUP($E4,'ip prosedur-2025'!$A:$H,4,FALSE) -> 1.1499459e+08 | M4: =VLOOKUP($E4,'ip prosedur-14 okt-15 juni 2026'!$A:$H,4,FALSE) -> 75994185 | N4: =VLOOKUP($E4,'ip prosedur-14 okt-15 juni 2026'!$A:$H,3, FALSE) -> 9 | O4: =M4*N4 -> 683947667 | P4: =VLOOKUP($E4,'ip prosedur-14 okt-15 juni 2026'!$A:$H,5,FALSE) -> 46214359 | Q4: =VLOOKUP($E4,'ip prosedur-14 okt-15 juni 2026'!$A:$H,6,FALSE) -> 69417899 | R4: =VLOOKUP($E4,'ip prosedur-14 okt-15 juni 2026'!$A:$H,7,FALSE) -> 101663598 | S4: =VLOOKUP($E4,'ip prosedur-14 okt-15 juni 2026'!$A:$H,8,FALSE) -> 167465700
A5: PDC | B5: 1 | C5: P16AB | D5: Stomach, Esophagus & Duodenal Resection Procedures | E5: 43.5 | F5: Partial gastrectomy with anastomosis to esophagus | G5: =VLOOKUP($E5,proc!$A:$D,3, FALSE) -> 5 | H5: =D5 -> Stomach, Esophagus & Duodenal Resection Procedures | I5: =C5 -> P16AB | J5: =VLOOKUP($C5,'tarif idrg'!$A:$O,11,FALSE) -> 18485238 | K5: =VLOOKUP($C5,'tarif idrg'!$A:$O,15,FALSE) -> 18485238 | L5: =VLOOKUP($E5,'ip prosedur-2025'!$A:$H,4,FALSE) -> 98744188 | M5: =VLOOKUP($E5,'ip prosedur-14 okt-15 juni 2026'!$A:$H,4,FALSE) -> 94617269 | N5: =VLOOKUP($E5,'ip prosedur-14 okt-15 juni 2026'!$A:$H,3, FALSE) -> 53 | O5: =M5*N5 -> 5014715278 | P5: =VLOOKUP($E5,'ip prosedur-14 okt-15 juni 2026'!$A:$H,5,FALSE) -> 42753297 | Q5: =VLOOKUP($E5,'ip prosedur-14 okt-15 juni 2026'!$A:$H,6,FALSE) -> 79648401 | R5: =VLOOKUP($E5,'ip prosedur-14 okt-15 juni 2026'!$A:$H,7,FALSE) -> 126490623 | S5: =VLOOKUP($E5,'ip prosedur-14 okt-15 juni 2026'!$A:$H,8,FALSE) -> 200440522
A6: PDC | B6: 1 | C6: P16AB | D6: Stomach, Esophagus & Duodenal Resection Procedures | E6: 43.6 | F6: Partial gastrectomy with anastomosis to duodenum | G6: =VLOOKUP($E6,proc!$A:$D,3, FALSE) -> 5 | H6: =D6 -> Stomach, Esophagus & Duodenal Resection Procedures | I6: =C6 -> P16AB | J6: =VLOOKUP($C6,'tarif idrg'!$A:$O,11,FALSE) -> 18485238 | K6: =VLOOKUP($C6,'tarif idrg'!$A:$O,15,FALSE) -> 18485238 | L6: =VLOOKUP($E6,'ip prosedur-2025'!$A:$H,4,FALSE) -> 75277649 | M6: =VLOOKUP($E6,'ip prosedur-14 okt-15 juni 2026'!$A:$H,4,FALSE) -> 72766392 | N6: =VLOOKUP($E6,'ip prosedur-14 okt-15 juni 2026'!$A:$H,3, FALSE) -> 58 | O6: =M6*N6 -> 4220450728 | P6: =VLOOKUP($E6,'ip prosedur-14 okt-15 juni 2026'!$A:$H,5,FALSE) -> 40672345 | Q6: =VLOOKUP($E6,'ip prosedur-14 okt-15 juni 2026'!$A:$H,6,FALSE) -> 58786202 | R6: =VLOOKUP($E6,'ip prosedur-14 okt-15 juni 2026'!$A:$H,7,FALSE) -> 91531996 | S6: =VLOOKUP($E6,'ip prosedur-14 okt-15 juni 2026'!$A:$H,8,FALSE) -> 148960900
A7: PDC | B7: 1 | C7: P16AB | D7: Stomach, Esophagus & Duodenal Resection Procedures | E7: 43.7 | F7: Partial gastrectomy with anastomosis to jejunum | G7: =VLOOKUP($E7,proc!$A:$D,3, FALSE) -> 6 | H7: =D7 -> Stomach, Esophagus & Duodenal Resection Procedures | I7: =C7 -> P16AB | J7: =VLOOKUP($C7,'tarif idrg'!$A:$O,11,FALSE) -> 18485238 | K7: =VLOOKUP($C7,'tarif idrg'!$A:$O,15,FALSE) -> 18485238 | L7: =VLOOKUP($E7,'ip prosedur-2025'!$A:$H,4,FALSE) -> 74462792 | M7: =VLOOKUP($E7,'ip prosedur-14 okt-15 juni 2026'!$A:$H,4,FALSE) -> 74421012 | N7: =VLOOKUP($E7,'ip prosedur-14 okt-15 juni 2026'!$A:$H,3, FALSE) -> 231 | O7: =M7*N7 -> 17191253712 | P7: =VLOOKUP($E7,'ip prosedur-14 okt-15 juni 2026'!$A:$H,5,FALSE) -> 34708610 | Q7: =VLOOKUP($E7,'ip prosedur-14 okt-15 juni 2026'!$A:$H,6,FALSE) -> 60993125 | R7: =VLOOKUP($E7,'ip prosedur-14 okt-15 juni 2026'!$A:$H,7,FALSE) -> 92240100 | S7: =VLOOKUP($E7,'ip prosedur-14 okt-15 juni 2026'!$A:$H,8,FALSE) -> 135701622
A8: PDC | B8: 1 | C8: P16AB | D8: Stomach, Esophagus & Duodenal Resection Procedures | E8: 43.81 | F8: Partial gastrectomy with jejunal transposition | G8: =VLOOKUP($E8,proc!$A:$D,3, FALSE) -> 6 | H8: =D8 -> Stomach, Esophagus & Duodenal Resection Procedures | I8: =C8 -> P16AB | J8: =VLOOKUP($C8,'tarif idrg'!$A:$O,11,FALSE) -> 18485238 | K8: =VLOOKUP($C8,'tarif idrg'!$A:$O,15,FALSE) -> 18485238 | L8: =VLOOKUP($E8,'ip prosedur-2025'!$A:$H,4,FALSE) -> 80525516 | M8: =VLOOKUP($E8,'ip prosedur-14 okt-15 juni 2026'!$A:$H,4,FALSE) -> 73089081 | N8: =VLOOKUP($E8,'ip prosedur-14 okt-15 juni 2026'!$A:$H,3, FALSE) -> 5 | O8: =M8*N8 -> 365445407 | P8: =VLOOKUP($E8,'ip prosedur-14 okt-15 juni 2026'!$A:$H,5,FALSE) -> 63276121 | Q8: =VLOOKUP($E8,'ip prosedur-14 okt-15 juni 2026'!$A:$H,6,FALSE) -> 70513922 | R8: =VLOOKUP($E8,'ip prosedur-14 okt-15 juni 2026'!$A:$H,7,FALSE) -> 82309664 | S8: =VLOOKUP($E8,'ip prosedur-14 okt-15 juni 2026'!$A:$H,8,FALSE) -> 104230307
A9: PDC | B9: 1 | C9: P16AB | D9: Stomach, Esophagus & Duodenal Resection Procedures | E9: 43.89 | F9: Other partial gastrectomy | G9: =VLOOKUP($E9,proc!$A:$D,3, FALSE) -> 5 | H9: =D9 -> Stomach, Esophagus & Duodenal Resection Procedures | I9: =C9 -> P16AB | J9: =VLOOKUP($C9,'tarif idrg'!$A:$O,11,FALSE) -> 18485238 | K9: =VLOOKUP($C9,'tarif idrg'!$A:$O,15,FALSE) -> 18485238 | L9: =VLOOKUP($E9,'ip prosedur-2025'!$A:$H,4,FALSE) -> 52574054 | M9: =VLOOKUP($E9,'ip prosedur-14 okt-15 juni 2026'!$A:$H,4,FALSE) -> 53324980 | N9: =VLOOKUP($E9,'ip prosedur-14 okt-15 juni 2026'!$A:$H,3, FALSE) -> 350 | O9: =M9*N9 -> 18663743053 | P9: =VLOOKUP($E9,'ip prosedur-14 okt-15 juni 2026'!$A:$H,5,FALSE) -> 20792502 | Q9: =VLOOKUP($E9,'ip prosedur-14 okt-15 juni 2026'!$A:$H,6,FALSE) -> 32577345 | R9: =VLOOKUP($E9,'ip prosedur-14 okt-15 juni 2026'!$A:$H,7,FALSE) -> 65702614 | S9: =VLOOKUP($E9,'ip prosedur-14 okt-15 juni 2026'!$A:$H,8,FALSE) -> 101884136
A10: PDC | B10: 1 | C10: P16AB | D10: Stomach, Esophagus & Duodenal Resection Procedures | E10: 43.91 | F10: Total gastrectomy with intestinal interposition | G10: =VLOOKUP($E10,proc!$A:$D,3, FALSE) -> 6 | H10: =D10 -> Stomach, Esophagus & Duodenal Resection Procedures | I10: =C10 -> P16AB | J10: =VLOOKUP($C10,'tarif idrg'!$A:$O,11,FALSE) -> 18485238 | K10: =VLOOKUP($C10,'tarif idrg'!$A:$O,15,FALSE) -> 18485238 | L10: =VLOOKUP($E10,'ip prosedur-2025'!$A:$H,4,FALSE) -> 1.1919652e+08 | M10: =VLOOKUP($E10,'ip prosedur-14 okt-15 juni 2026'!$A:$H,4,FALSE) -> 1.4422502e+08 | N10: =VLOOKUP($E10,'ip prosedur-14 okt-15 juni 2026'!$A:$H,3, FALSE) -> 10 | O10: =M10*N10 -> 1442250236 | P10: =VLOOKUP($E10,'ip prosedur-14 okt-15 juni 2026'!$A:$H,5,FALSE) -> 85870232 | Q10: =VLOOKUP($E10,'ip prosedur-14 okt-15 juni 2026'!$A:$H,6,FALSE) -> 92324883 | R10: =VLOOKUP($E10,'ip prosedur-14 okt-15 juni 2026'!$A:$H,7,FALSE) -> 151293741 | S10: =VLOOKUP($E10,'ip prosedur-14 okt-15 juni 2026'!$A:$H,8,FALSE) -> 205202294
A11: PDC | B11: 1 | C11: P16AB | D11: Stomach, Esophagus & Duodenal Resection Procedures | E11: 43.99 | F11: Other total gastrectomy | G11: =VLOOKUP($E11,proc!$A:$D,3, FALSE) -> 6 | H11: =D11 -> Stomach, Esophagus & Duodenal Resection Procedures | I11: =C11 -> P16AB | J11: =VLOOKUP($C11,'tarif idrg'!$A:$O,11,FALSE) -> 18485238 | K11: =VLOOKUP($C11,'tarif idrg'!$A:$O,15,FALSE) -> 18485238 | L11: =VLOOKUP($E11,'ip prosedur-2025'!$A:$H,4,FALSE) -> 87655495 | M11: =VLOOKUP($E11,'ip prosedur-14 okt-15 juni 2026'!$A:$H,4,FALSE) -> 1.1048437e+08 | N11: =VLOOKUP($E11,'ip prosedur-14 okt-15 juni 2026'!$A:$H,3, FALSE) -> 45 | O11: =M11*N11 -> 4971796542 | P11: =VLOOKUP($E11,'ip prosedur-14 okt-15 juni 2026'!$A:$H,5,FALSE) -> 43422908 | Q11: =VLOOKUP($E11,'ip prosedur-14 okt-15 juni 2026'!$A:$H,6,FALSE) -> 91403368 | R11: =VLOOKUP($E11,'ip prosedur-14 okt-15 juni 2026'!$A:$H,7,FALSE) -> 122210336 | S11: =VLOOKUP($E11,'ip prosedur-14 okt-15 juni 2026'!$A:$H,8,FALSE) -> 234211982
A12: PDC | B12: 1 | C12: P16AD | D12: Rectal Resection Procedures | E12: 48.0 | F12: Proctotomy | G12: =VLOOKUP($E12,proc!$A:$D,3, FALSE) -> 4 | H12: =D12 -> Rectal Resection Procedures | I12: =C12 -> P16AD | J12: =VLOOKUP($C12,'tarif idrg'!$A:$O,11,FALSE) -> 19047832 | K12: =VLOOKUP($C12,'tarif idrg'!$A:$O,15,FALSE) -> 19047832 | L12: =VLOOKUP($E12,'ip prosedur-2025'!$A:$H,4,FALSE) -> 19959087 | M12: =VLOOKUP($E12,'ip prosedur-14 okt-15 juni 2026'!$A:$H,4,FALSE) -> 17114671 | N12: =VLOOKUP($E12,'ip prosedur-14 okt-15 juni 2026'!$A:$H,3, FALSE) -> 30 | O12: =M12*N12 -> 513440133 | P12: =VLOOKUP($E12,'ip prosedur-14 okt-15 juni 2026'!$A:$H,5,FALSE) -> 7283797 | Q12: =VLOOKUP($E12,'ip prosedur-14 okt-15 juni 2026'!$A:$H,6,FALSE) -> 13968995 | R12: =VLOOKUP($E12,'ip prosedur-14 okt-15 juni 2026'!$A:$H,7,FALSE) -> 25205333 | S12: =VLOOKUP($E12,'ip prosedur-14 okt-15 juni 2026'!$A:$H,8,FALSE) -> 32847476
A13: PDC | B13: 1 | C13: P16AD | D13: Rectal Resection Procedures | E13: 48.40 | F13: Pull-through resection of rectum, not otherwise specified | G13: =VLOOKUP($E13,proc!$A:$D,3, FALSE) -> 5 | H13: =D13 -> Rectal Resection Procedures | I13: =C13 -> P16AD | J13: =VLOOKUP($C13,'tarif idrg'!$A:$O,11,FALSE) -> 19047832 | K13: =VLOOKUP($C13,'tarif idrg'!$A:$O,15,FALSE) -> 19047832 | L13: =VLOOKUP($E13,'ip prosedur-2025'!$A:$H,4,FALSE) -> 40360689 | M13: =VLOOKUP($E13,'ip prosedur-14 okt-15 juni 2026'!$A:$H,4,FALSE) -> 34725012 | N13: =VLOOKUP($E13,'ip prosedur-14 okt-15 juni 2026'!$A:$H,3, FALSE) -> 132 | O13: =M13*N13 -> 4583701558 | P13: =VLOOKUP($E13,'ip prosedur-14 okt-15 juni 2026'!$A:$H,5,FALSE) -> 15014000 | Q13: =VLOOKUP($E13,'ip prosedur-14 okt-15 juni 2026'!$A:$H,6,FALSE) -> 23447487 | R13: =VLOOKUP($E13,'ip prosedur-14 okt-15 juni 2026'!$A:$H,7,FALSE) -> 33824388 | S13: =VLOOKUP($E13,'ip prosedur-14 okt-15 juni 2026'!$A:$H,8,FALSE) -> 57323242
... A218: PDC | B218: 1 | C218: P16AR | D218: Complex Therapeutic Colonoscopy | E218: 45.43 | F218: Endoscopic destruction of other lesion or tissue of large intestine | G218: =VLOOKUP($E218,proc!$A:$D,3, FALSE) -> 0 | H218: =D218 -> Complex Therapeutic Colonoscopy | I218: =C218 -> P16AR | J218: =VLOOKUP($C218,'tarif idrg'!$A:$O,11,FALSE) -> 4822236 | K218: =VLOOKUP($C218,'tarif idrg'!$A:$O,15,FALSE) -> 4822236 | L218: =VLOOKUP($E218,'ip prosedur-2025'!$A:$H,4,FALSE) -> 22653031 | M218: =VLOOKUP($E218,'ip prosedur-14 okt-15 juni 2026'!$A:$H,4,FALSE) -> 23169771 | N218: =VLOOKUP($E218,'ip prosedur-14 okt-15 juni 2026'!$A:$H,3, FALSE) -> 149 | O218: =M218*N218 -> 3452295822 | P218: =VLOOKUP($E218,'ip prosedur-14 okt-15 juni 2026'!$A:$H,5,FALSE) -> 7029841 | Q218: =VLOOKUP($E218,'ip prosedur-14 okt-15 juni 2026'!$A:$H,6,FALSE) -> 17173400 | R218: =VLOOKUP($E218,'ip prosedur-14 okt-15 juni 2026'!$A:$H,7,FALSE) -> 31940856 | S218: =VLOOKUP($E218,'ip prosedur-14 okt-15 juni 2026'!$A:$H,8,FALSE) -> 39472470
A219: PDC | B219: 1 | C219: P16AJ | D219: Minor Small and Large Bowel Procedures | E219: PDC | G219: =VLOOKUP($E219,proc!$A:$D,3, FALSE) -> #N/A | H219: =D219 -> Minor Small and Large Bowel Procedures | I219: =C219 -> P16AJ | J219: =VLOOKUP($C219,'tarif idrg'!$A:$O,11,FALSE) -> #N/A | K219: =VLOOKUP($C219,'tarif idrg'!$A:$O,15,FALSE) -> #N/A | L219: =VLOOKUP($E219,'ip prosedur-2025'!$A:$H,4,FALSE) -> #N/A | M219: =VLOOKUP($E219,'ip prosedur-14 okt-15 juni 2026'!$A:$H,4,FALSE) -> #N/A | N219: =VLOOKUP($E219,'ip prosedur-14 okt-15 juni 2026'!$A:$H,3, FALSE) -> #N/A | O219: =M219*N219 -> #N/A | P219: =VLOOKUP($E219,'ip prosedur-14 okt-15 juni 2026'!$A:$H,5,FALSE) -> #N/A | Q219: =VLOOKUP($E219,'ip prosedur-14 okt-15 juni 2026'!$A:$H,6,FALSE) -> #N/A | R219: =VLOOKUP($E219,'ip prosedur-14 okt-15 juni 2026'!$A:$H,7,FALSE) -> #N/A | S219: =VLOOKUP($E219,'ip prosedur-14 okt-15 juni 2026'!$A:$H,8,FALSE) -> #N/A
A220: PDC | B220: 1 | C220: P16AJ | D220: Minor Small and Large Bowel Procedures | E220: 45.02 | F220: Other incision of small intestine | G220: =VLOOKUP($E220,proc!$A:$D,3, FALSE) -> 4 | H220: =D220 -> Minor Small and Large Bowel Procedures | I220: =C220 -> P16AJ | J220: =VLOOKUP($C220,'tarif idrg'!$A:$O,11,FALSE) -> #N/A | K220: =VLOOKUP($C220,'tarif idrg'!$A:$O,15,FALSE) -> #N/A | L220: =VLOOKUP($E220,'ip prosedur-2025'!$A:$H,4,FALSE) -> 47327291 | M220: =VLOOKUP($E220,'ip prosedur-14 okt-15 juni 2026'!$A:$H,4,FALSE) -> 54690432 | N220: =VLOOKUP($E220,'ip prosedur-14 okt-15 juni 2026'!$A:$H,3, FALSE) -> 94 | O220: =M220*N220 -> 5140900608 | P220: =VLOOKUP($E220,'ip prosedur-14 okt-15 juni 2026'!$A:$H,5,FALSE) -> 17362785 | Q220: =VLOOKUP($E220,'ip prosedur-14 okt-15 juni 2026'!$A:$H,6,FALSE) -> 32814821 | R220: =VLOOKUP($E220,'ip prosedur-14 okt-15 juni 2026'!$A:$H,7,FALSE) -> 66778900 | S220: =VLOOKUP($E220,'ip prosedur-14 okt-15 juni 2026'!$A:$H,8,FALSE) -> 121182345
A221: PDC | B221: 1 | C221: P16AJ | D221: Minor Small and Large Bowel Procedures | E221: 45.03 | F221: Incision of large intestine | G221: =VLOOKUP($E221,proc!$A:$D,3, FALSE) -> 4 | H221: =D221 -> Minor Small and Large Bowel Procedures | I221: =C221 -> P16AJ | J221: =VLOOKUP($C221,'tarif idrg'!$A:$O,11,FALSE) -> #N/A | K221: =VLOOKUP($C221,'tarif idrg'!$A:$O,15,FALSE) -> #N/A | L221: =VLOOKUP($E221,'ip prosedur-2025'!$A:$H,4,FALSE) -> 56875818 | M221: =VLOOKUP($E221,'ip prosedur-14 okt-15 juni 2026'!$A:$H,4,FALSE) -> 44744856 | N221: =VLOOKUP($E221,'ip prosedur-14 okt-15 juni 2026'!$A:$H,3, FALSE) -> 108 | O221: =M221*N221 -> 4832444400 | P221: =VLOOKUP($E221,'ip prosedur-14 okt-15 juni 2026'!$A:$H,5,FALSE) -> 19368463 | Q221: =VLOOKUP($E221,'ip prosedur-14 okt-15 juni 2026'!$A:$H,6,FALSE) -> 32688098 | R221: =VLOOKUP($E221,'ip prosedur-14 okt-15 juni 2026'!$A:$H,7,FALSE) -> 51267949 | S221: =VLOOKUP($E221,'ip prosedur-14 okt-15 juni 2026'!$A:$H,8,FALSE) -> 92616208
A222: PDC | B222: 1 | C222: P16AJ | D222: Minor Small and Large Bowel Procedures | E222: 45.11 | F222: Transabdominal endoscopy of small intestine | G222: =VLOOKUP($E222,proc!$A:$D,3, FALSE) -> 0 | H222: =D222 -> Minor Small and Large Bowel Procedures | I222: =C222 -> P16AJ | J222: =VLOOKUP($C222,'tarif idrg'!$A:$O,11,FALSE) -> #N/A | K222: =VLOOKUP($C222,'tarif idrg'!$A:$O,15,FALSE) -> #N/A | L222: =VLOOKUP($E222,'ip prosedur-2025'!$A:$H,4,FALSE) -> 19692268 | M222: =VLOOKUP($E222,'ip prosedur-14 okt-15 juni 2026'!$A:$H,4,FALSE) -> 34061280 | N222: =VLOOKUP($E222,'ip prosedur-14 okt-15 juni 2026'!$A:$H,3, FALSE) -> 17 | O222: =M222*N222 -> 579041759 | P222: =VLOOKUP($E222,'ip prosedur-14 okt-15 juni 2026'!$A:$H,5,FALSE) -> 12377427 | Q222: =VLOOKUP($E222,'ip prosedur-14 okt-15 juni 2026'!$A:$H,6,FALSE) -> 15374613 | R222: =VLOOKUP($E222,'ip prosedur-14 okt-15 juni 2026'!$A:$H,7,FALSE) -> 44843982 | S222: =VLOOKUP($E222,'ip prosedur-14 okt-15 juni 2026'!$A:$H,8,FALSE) -> 88059127
A223: PDC | B223: 1 | C223: P16AJ | D223: Minor Small and Large Bowel Procedures | E223: 45.15 | F223: Open biopsy of small intestine | G223: =VLOOKUP($E223,proc!$A:$D,3, FALSE) -> 4 | H223: =D223 -> Minor Small and Large Bowel Procedures | I223: =C223 -> P16AJ | J223: =VLOOKUP($C223,'tarif idrg'!$A:$O,11,FALSE) -> #N/A | K223: =VLOOKUP($C223,'tarif idrg'!$A:$O,15,FALSE) -> #N/A | L223: =VLOOKUP($E223,'ip prosedur-2025'!$A:$H,4,FALSE) -> 33645451 | M223: =VLOOKUP($E223,'ip prosedur-14 okt-15 juni 2026'!$A:$H,4,FALSE) -> 35811168 | N223: =VLOOKUP($E223,'ip prosedur-14 okt-15 juni 2026'!$A:$H,3, FALSE) -> 396 | O223: =M223*N223 -> 14181222425 | P223: =VLOOKUP($E223,'ip prosedur-14 okt-15 juni 2026'!$A:$H,5,FALSE) -> 15015039 | Q223: =VLOOKUP($E223,'ip prosedur-14 okt-15 juni 2026'!$A:$H,6,FALSE) -> 23930024 | R223: =VLOOKUP($E223,'ip prosedur-14 okt-15 juni 2026'!$A:$H,7,FALSE) -> 43515833 | S223: =VLOOKUP($E223,'ip prosedur-14 okt-15 juni 2026'!$A:$H,8,FALSE) -> 73132299
A224: PDC | B224: 1 | C224: P16AJ | D224: Minor Small and Large Bowel Procedures | E224: 45.19 | F224: Other diagnostic procedures on small intestine | G224: =VLOOKUP($E224,proc!$A:$D,3, FALSE) -> 0 | H224: =D224 -> Minor Small and Large Bowel Procedures | I224: =C224 -> P16AJ | J224: =VLOOKUP($C224,'tarif idrg'!$A:$O,11,FALSE) -> #N/A | K224: =VLOOKUP($C224,'tarif idrg'!$A:$O,15,FALSE) -> #N/A | L224: =VLOOKUP($E224,'ip prosedur-2025'!$A:$H,4,FALSE) -> 30629622 | M224: =VLOOKUP($E224,'ip prosedur-14 okt-15 juni 2026'!$A:$H,4,FALSE) -> 31869876 | N224: =VLOOKUP($E224,'ip prosedur-14 okt-15 juni 2026'!$A:$H,3, FALSE) -> 22 | O224: =M224*N224 -> 701137279 | P224: =VLOOKUP($E224,'ip prosedur-14 okt-15 juni 2026'!$A:$H,5,FALSE) -> 11035132 | Q224: =VLOOKUP($E224,'ip prosedur-14 okt-15 juni 2026'!$A:$H,6,FALSE) -> 15911016 | R224: =VLOOKUP($E224,'ip prosedur-14 okt-15 juni 2026'!$A:$H,7,FALSE) -> 29372655 | S224: =VLOOKUP($E224,'ip prosedur-14 okt-15 juni 2026'!$A:$H,8,FALSE) -> 56264468
A225: PDC | B225: 1 | C225: P16AJ | D225: Minor Small and Large Bowel Procedures | E225: 45.26 | F225: Open biopsy of large intestine | G225: =VLOOKUP($E225,proc!$A:$D,3, FALSE) -> 4 | H225: =D225 -> Minor Small and Large Bowel Procedures | I225: =C225 -> P16AJ | J225: =VLOOKUP($C225,'tarif idrg'!$A:$O,11,FALSE) -> #N/A | K225: =VLOOKUP($C225,'tarif idrg'!$A:$O,15,FALSE) -> #N/A | L225: =VLOOKUP($E225,'ip prosedur-2025'!$A:$H,4,FALSE) -> 28311589 | M225: =VLOOKUP($E225,'ip prosedur-14 okt-15 juni 2026'!$A:$H,4,FALSE) -> 28227707 | N225: =VLOOKUP($E225,'ip prosedur-14 okt-15 juni 2026'!$A:$H,3, FALSE) -> 1532 | O225: =M225*N225 -> 43244847078 | P225: =VLOOKUP($E225,'ip prosedur-14 okt-15 juni 2026'!$A:$H,5,FALSE) -> 13812279 | Q225: =VLOOKUP($E225,'ip prosedur-14 okt-15 juni 2026'!$A:$H,6,FALSE) -> 19752805 | R225: =VLOOKUP($E225,'ip prosedur-14 okt-15 juni 2026'!$A:$H,7,FALSE) -> 30867651 | S225: =VLOOKUP($E225,'ip prosedur-14 okt-15 juni 2026'!$A:$H,8,FALSE) -> 52640969
A226: PDC | B226: 1 | C226: P16AJ | D226: Minor Small and Large Bowel Procedures | E226: 45.27 | F226: Intestinal biopsy, site unspecified | G226: =VLOOKUP($E226,proc!$A:$D,3, FALSE) -> 0 | H226: =D226 -> Minor Small and Large Bowel Procedures | I226: =C226 -> P16AJ | J226: =VLOOKUP($C226,'tarif idrg'!$A:$O,11,FALSE) -> #N/A | K226: =VLOOKUP($C226,'tarif idrg'!$A:$O,15,FALSE) -> #N/A | L226: =VLOOKUP($E226,'ip prosedur-2025'!$A:$H,4,FALSE) -> 26523378 | M226: =VLOOKUP($E226,'ip prosedur-14 okt-15 juni 2026'!$A:$H,4,FALSE) -> 25600631 | N226: =VLOOKUP($E226,'ip prosedur-14 okt-15 juni 2026'!$A:$H,3, FALSE) -> 136 | O226: =M226*N226 -> 3481685755 | P226: =VLOOKUP($E226,'ip prosedur-14 okt-15 juni 2026'!$A:$H,5,FALSE) -> 14368033 | Q226: =VLOOKUP($E226,'ip prosedur-14 okt-15 juni 2026'!$A:$H,6,FALSE) -> 19608499 | R226: =VLOOKUP($E226,'ip prosedur-14 okt-15 juni 2026'!$A:$H,7,FALSE) -> 32608965 | S226: =VLOOKUP($E226,'ip prosedur-14 okt-15 juni 2026'!$A:$H,8,FALSE) -> 45232826
A227: PDC | B227: 1 | C227: P16AJ | D227: Minor Small and Large Bowel Procedures | E227: 45.28 | F227: Other diagnostic procedures on large intestine | G227: =VLOOKUP($E227,proc!$A:$D,3, FALSE) -> 0 | H227: =D227 -> Minor Small and Large Bowel Procedures | I227: =C227 -> P16AJ | J227: =VLOOKUP($C227,'tarif idrg'!$A:$O,11,FALSE) -> #N/A | K227: =VLOOKUP($C227,'tarif idrg'!$A:$O,15,FALSE) -> #N/A | L227: =VLOOKUP($E227,'ip prosedur-2025'!$A:$H,4,FALSE) -> 25116833 | M227: =VLOOKUP($E227,'ip prosedur-14 okt-15 juni 2026'!$A:$H,4,FALSE) -> 17245994 | N227: =VLOOKUP($E227,'ip prosedur-14 okt-15 juni 2026'!$A:$H,3, FALSE) -> 6 | O227: =M227*N227 -> 103475964 | P227: =VLOOKUP($E227,'ip prosedur-14 okt-15 juni 2026'!$A:$H,5,FALSE) -> 3638415 | Q227: =VLOOKUP($E227,'ip prosedur-14 okt-15 juni 2026'!$A:$H,6,FALSE) -> 8176357 | R227: =VLOOKUP($E227,'ip prosedur-14 okt-15 juni 2026'!$A:$H,7,FALSE) -> 17306350 | S227: =VLOOKUP($E227,'ip prosedur-14 okt-15 juni 2026'!$A:$H,8,FALSE) -> 59574775
A228: PDC | B228: 1 | C228: P16AJ | D228: Minor Small and Large Bowel Procedures | E228: 45.34 | F228: Other destruction of lesion of small intestine, except duodenum | G228: =VLOOKUP($E228,proc!$A:$D,3, FALSE) -> 4 | H228: =D228 -> Minor Small and Large Bowel Procedures | I228: =C228 -> P16AJ | J228: =VLOOKUP($C228,'tarif idrg'!$A:$O,11,FALSE) -> #N/A | K228: =VLOOKUP($C228,'tarif idrg'!$A:$O,15,FALSE) -> #N/A | L228: =VLOOKUP($E228,'ip prosedur-2025'!$A:$H,4,FALSE) -> 39306713 | M228: =VLOOKUP($E228,'ip prosedur-14 okt-15 juni 2026'!$A:$H,4,FALSE) -> 56542585 | N228: =VLOOKUP($E228,'ip prosedur-14 okt-15 juni 2026'!$A:$H,3, FALSE) -> 39 | O228: =M228*N228 -> 2205160798 | P228: =VLOOKUP($E228,'ip prosedur-14 okt-15 juni 2026'!$A:$H,5,FALSE) -> 16913293 | Q228: =VLOOKUP($E228,'ip prosedur-14 okt-15 juni 2026'!$A:$H,6,FALSE) -> 25618104 | R228: =VLOOKUP($E228,'ip prosedur-14 okt-15 juni 2026'!$A:$H,7,FALSE) -> 62026445 | S228: =VLOOKUP($E228,'ip prosedur-14 okt-15 juni 2026'!$A:$H,8,FALSE) -> 152417404
A229: PDC | B229: 1 | C229: P16AJ | D229: Minor Small and Large Bowel Procedures | E229: 45.49 | F229: Other destruction of lesion of large intestine | G229: =VLOOKUP($E229,proc!$A:$D,3, FALSE) -> 4 | H229: =D229 -> Minor Small and Large Bowel Procedures | I229: =C229 -> P16AJ | J229: =VLOOKUP($C229,'tarif idrg'!$A:$O,11,FALSE) -> #N/A | K229: =VLOOKUP($C229,'tarif idrg'!$A:$O,15,FALSE) -> #N/A | L229: =VLOOKUP($E229,'ip prosedur-2025'!$A:$H,4,FALSE) -> 30218864 | M229: =VLOOKUP($E229,'ip prosedur-14 okt-15 juni 2026'!$A:$H,4,FALSE) -> 44598676 | N229: =VLOOKUP($E229,'ip prosedur-14 okt-15 juni 2026'!$A:$H,3, FALSE) -> 56 | O229: =M229*N229 -> 2497525866 | P229: =VLOOKUP($E229,'ip prosedur-14 okt-15 juni 2026'!$A:$H,5,FALSE) -> 15186078 | Q229: =VLOOKUP($E229,'ip prosedur-14 okt-15 juni 2026'!$A:$H,6,FALSE) -> 25649925 | R229: =VLOOKUP($E229,'ip prosedur-14 okt-15 juni 2026'!$A:$H,7,FALSE) -> 57426200 | S229: =VLOOKUP($E229,'ip prosedur-14 okt-15 juni 2026'!$A:$H,8,FALSE) -> 101155350
A230: PDC | B230: 1 | C230: P16AJ | D230: Minor Small and Large Bowel Procedures | E230: 45.50 | F230: Isolation of intestinal segment, not otherwise specified | G230: =VLOOKUP($E230,proc!$A:$D,3, FALSE) -> 5 | H230: =D230 -> Minor Small and Large Bowel Procedures | I230: =C230 -> P16AJ | J230: =VLOOKUP($C230,'tarif idrg'!$A:$O,11,FALSE) -> #N/A | K230: =VLOOKUP($C230,'tarif idrg'!$A:$O,15,FALSE) -> #N/A | L230: =VLOOKUP($E230,'ip prosedur-2025'!$A:$H,4,FALSE) -> 1.705323e+08 | M230: =VLOOKUP($E230,'ip prosedur-14 okt-15 juni 2026'!$A:$H,4,FALSE) -> 42031596 | N230: =VLOOKUP($E230,'ip prosedur-14 okt-15 juni 2026'!$A:$H,3, FALSE) -> 7 | O230: =M230*N230 -> 294221171 | P230: =VLOOKUP($E230,'ip prosedur-14 okt-15 juni 2026'!$A:$H,5,FALSE) -> 8756700 | Q230: =VLOOKUP($E230,'ip prosedur-14 okt-15 juni 2026'!$A:$H,6,FALSE) -> 30049243 | R230: =VLOOKUP($E230,'ip prosedur-14 okt-15 juni 2026'!$A:$H,7,FALSE) -> 40729704 | S230: =VLOOKUP($E230,'ip prosedur-14 okt-15 juni 2026'!$A:$H,8,FALSE) -> 150314277
A231: PDC | B231: 1 | C231: P16AJ | D231: Minor Small and Large Bowel Procedures | E231: 46.60 | F231: Fixation of intestine, not otherwise specified | G231: =VLOOKUP($E231,proc!$A:$D,3, FALSE) -> 3 | H231: =D231 -> Minor Small and Large Bowel Procedures | I231: =C231 -> P16AJ | J231: =VLOOKUP($C231,'tarif idrg'!$A:$O,11,FALSE) -> #N/A | K231: =VLOOKUP($C231,'tarif idrg'!$A:$O,15,FALSE) -> #N/A | L231: =VLOOKUP($E231,'ip prosedur-2025'!$A:$H,4,FALSE) -> 42958161 | M231: =VLOOKUP($E231,'ip prosedur-14 okt-15 juni 2026'!$A:$H,4,FALSE) -> 30529292 | N231: =VLOOKUP($E231,'ip prosedur-14 okt-15 juni 2026'!$A:$H,3, FALSE) -> 9 | O231: =M231*N231 -> 274763628 | P231: =VLOOKUP($E231,'ip prosedur-14 okt-15 juni 2026'!$A:$H,5,FALSE) -> 12105065 | Q231: =VLOOKUP($E231,'ip prosedur-14 okt-15 juni 2026'!$A:$H,6,FALSE) -> 15846995 | R231: =VLOOKUP($E231,'ip prosedur-14 okt-15 juni 2026'!$A:$H,7,FALSE) -> 28243600 | S231: =VLOOKUP($E231,'ip prosedur-14 okt-15 juni 2026'!$A:$H,8,FALSE) -> 94674006
... A618: PDC | B618: 2 | C618: P16KW | D618: Other Gastrointestinal Minor Proc. | E618: 99.93 | F618: Rectal massage (for levator spasm) | G618: =VLOOKUP($E618,proc!$A:$D,3, FALSE) -> 0 | H618: =D618 -> Other Gastrointestinal Minor Proc. | I618: =C618 -> P16KW | J618: =VLOOKUP($C618,'tarif idrg'!$A:$O,11,FALSE) -> 406097 | K618: =VLOOKUP($C618,'tarif idrg'!$A:$O,15,FALSE) -> 406097 | L618: =VLOOKUP($E618,'ip prosedur-2025'!$A:$H,4,FALSE) -> 8114314.6 | M618: =VLOOKUP($E618,'ip prosedur-14 okt-15 juni 2026'!$A:$H,4,FALSE) -> 9015433.5 | N618: =VLOOKUP($E618,'ip prosedur-14 okt-15 juni 2026'!$A:$H,3, FALSE) -> 13 | O618: =M618*N618 -> 117200635 | P618: =VLOOKUP($E618,'ip prosedur-14 okt-15 juni 2026'!$A:$H,5,FALSE) -> 3443578 | Q618: =VLOOKUP($E618,'ip prosedur-14 okt-15 juni 2026'!$A:$H,6,FALSE) -> 7922125 | R618: =VLOOKUP($E618,'ip prosedur-14 okt-15 juni 2026'!$A:$H,7,FALSE) -> 13353121 | S618: =VLOOKUP($E618,'ip prosedur-14 okt-15 juni 2026'!$A:$H,8,FALSE) -> 17433656

Sheet ranap cluster
A1: Cluster Type | B1: Cluster Code | C1: Cluster Description | D1: ICD9CM Code | E1: ICD9CM Description | F1: procgr | G1: New Cluster Descrirption | H1: New Cluster Code | I1: Action | J1: Notes | K1: tarif iDRG | L1: tarif iDRG + AF | M1: Check rajal | N1: Check Changes | O1: tarif rs 2025 | P1: tarif rs uji coba | Q1: Jumlah Kasus | R1: Total | S1: p25 uji coba | T1: p50 uji coba | U1: p75 uji coba | V1: p90 uji coba | W1: Kompetensi | X1: Layanan
A2: PDC | B2: P16AB | C2: Stomach, Esophagus & Duodenal Resection Procedures | D2: 41.5 | E2: Total splenectomy | F2: =VLOOKUP($D2,proc!$A:$D,3, FALSE) -> 4 | G2: =C2 -> Stomach, Esophagus & Duodenal Resection Procedures | H2: =B2 -> P16AB | K2: =VLOOKUP($B2,'tarif idrg'!$A:$O,11,FALSE) -> 18485238 | L2: =VLOOKUP($B2,'tarif idrg'!$A:$O,15,FALSE) -> 18485238 | N2: =IF(C2<>G2,"Change","-") -> - | O2: =VLOOKUP($D2,'ip prosedur-2025'!$A:$H,4,FALSE) -> 52429636 | P2: =VLOOKUP($D2,'ip prosedur-14 okt-15 juni 2026'!$A:$H,4,FALSE) -> 52865089 | Q2: =VLOOKUP($D2,'ip prosedur-14 okt-15 juni 2026'!$A:$H,3, FALSE) -> 543 | R2: =P2*Q2 -> 28705743414 | S2: =VLOOKUP($D2,'ip prosedur-14 okt-15 juni 2026'!$A:$H,5,FALSE) -> 24391385 | T2: =VLOOKUP($D2,'ip prosedur-14 okt-15 juni 2026'!$A:$H,6,FALSE) -> 37323000 | U2: =VLOOKUP($D2,'ip prosedur-14 okt-15 juni 2026'!$A:$H,7,FALSE) -> 62092164 | V2: =VLOOKUP($D2,'ip prosedur-14 okt-15 juni 2026'!$A:$H,8,FALSE) -> 102438900
A3: PDC | B3: P16AB | C3: Stomach, Esophagus & Duodenal Resection Procedures | D3: 42.41 | E3: Partial esophagectomy | F3: =VLOOKUP($D3,proc!$A:$D,3, FALSE) -> 6 | G3: =C3 -> Stomach, Esophagus & Duodenal Resection Procedures | H3: =B3 -> P16AB | K3: =VLOOKUP($B3,'tarif idrg'!$A:$O,11,FALSE) -> 18485238 | L3: =VLOOKUP($B3,'tarif idrg'!$A:$O,15,FALSE) -> 18485238 | N3: =IF(C3<>G3,"Change","-") -> - | O3: =VLOOKUP($D3,'ip prosedur-2025'!$A:$H,4,FALSE) -> 1.2611458e+08 | P3: =VLOOKUP($D3,'ip prosedur-14 okt-15 juni 2026'!$A:$H,4,FALSE) -> 1.1940485e+08 | Q3: =VLOOKUP($D3,'ip prosedur-14 okt-15 juni 2026'!$A:$H,3, FALSE) -> 43 | R3: =P3*Q3 -> 5134408520 | S3: =VLOOKUP($D3,'ip prosedur-14 okt-15 juni 2026'!$A:$H,5,FALSE) -> 53608899 | T3: =VLOOKUP($D3,'ip prosedur-14 okt-15 juni 2026'!$A:$H,6,FALSE) -> 108589810 | U3: =VLOOKUP($D3,'ip prosedur-14 okt-15 juni 2026'!$A:$H,7,FALSE) -> 157989413 | V3: =VLOOKUP($D3,'ip prosedur-14 okt-15 juni 2026'!$A:$H,8,FALSE) -> 205202294
A4: PDC | B4: P16AB | C4: Stomach, Esophagus & Duodenal Resection Procedures | D4: 42.42 | E4: Total esophagectomy | F4: =VLOOKUP($D4,proc!$A:$D,3, FALSE) -> 6 | G4: =C4 -> Stomach, Esophagus & Duodenal Resection Procedures | H4: =B4 -> P16AB | K4: =VLOOKUP($B4,'tarif idrg'!$A:$O,11,FALSE) -> 18485238 | L4: =VLOOKUP($B4,'tarif idrg'!$A:$O,15,FALSE) -> 18485238 | N4: =IF(C4<>G4,"Change","-") -> - | O4: =VLOOKUP($D4,'ip prosedur-2025'!$A:$H,4,FALSE) -> 1.1499459e+08 | P4: =VLOOKUP($D4,'ip prosedur-14 okt-15 juni 2026'!$A:$H,4,FALSE) -> 75994185 | Q4: =VLOOKUP($D4,'ip prosedur-14 okt-15 juni 2026'!$A:$H,3, FALSE) -> 9 | R4: =P4*Q4 -> 683947667 | S4: =VLOOKUP($D4,'ip prosedur-14 okt-15 juni 2026'!$A:$H,5,FALSE) -> 46214359 | T4: =VLOOKUP($D4,'ip prosedur-14 okt-15 juni 2026'!$A:$H,6,FALSE) -> 69417899 | U4: =VLOOKUP($D4,'ip prosedur-14 okt-15 juni 2026'!$A:$H,7,FALSE) -> 101663598 | V4: =VLOOKUP($D4,'ip prosedur-14 okt-15 juni 2026'!$A:$H,8,FALSE) -> 167465700
A5: PDC | B5: P16AB | C5: Stomach, Esophagus & Duodenal Resection Procedures | D5: 43.5 | E5: Partial gastrectomy with anastomosis to esophagus | F5: =VLOOKUP($D5,proc!$A:$D,3, FALSE) -> 5 | G5: =C5 -> Stomach, Esophagus & Duodenal Resection Procedures | H5: =B5 -> P16AB | K5: =VLOOKUP($B5,'tarif idrg'!$A:$O,11,FALSE) -> 18485238 | L5: =VLOOKUP($B5,'tarif idrg'!$A:$O,15,FALSE) -> 18485238 | N5: =IF(C5<>G5,"Change","-") -> - | O5: =VLOOKUP($D5,'ip prosedur-2025'!$A:$H,4,FALSE) -> 98744188 | P5: =VLOOKUP($D5,'ip prosedur-14 okt-15 juni 2026'!$A:$H,4,FALSE) -> 94617269 | Q5: =VLOOKUP($D5,'ip prosedur-14 okt-15 juni 2026'!$A:$H,3, FALSE) -> 53 | R5: =P5*Q5 -> 5014715278 | S5: =VLOOKUP($D5,'ip prosedur-14 okt-15 juni 2026'!$A:$H,5,FALSE) -> 42753297 | T5: =VLOOKUP($D5,'ip prosedur-14 okt-15 juni 2026'!$A:$H,6,FALSE) -> 79648401 | U5: =VLOOKUP($D5,'ip prosedur-14 okt-15 juni 2026'!$A:$H,7,FALSE) -> 126490623 | V5: =VLOOKUP($D5,'ip prosedur-14 okt-15 juni 2026'!$A:$H,8,FALSE) -> 200440522
A6: PDC | B6: P16AB | C6: Stomach, Esophagus & Duodenal Resection Procedures | D6: 43.6 | E6: Partial gastrectomy with anastomosis to duodenum | F6: =VLOOKUP($D6,proc!$A:$D,3, FALSE) -> 5 | G6: =C6 -> Stomach, Esophagus & Duodenal Resection Procedures | H6: =B6 -> P16AB | K6: =VLOOKUP($B6,'tarif idrg'!$A:$O,11,FALSE) -> 18485238 | L6: =VLOOKUP($B6,'tarif idrg'!$A:$O,15,FALSE) -> 18485238 | N6: =IF(C6<>G6,"Change","-") -> - | O6: =VLOOKUP($D6,'ip prosedur-2025'!$A:$H,4,FALSE) -> 75277649 | P6: =VLOOKUP($D6,'ip prosedur-14 okt-15 juni 2026'!$A:$H,4,FALSE) -> 72766392 | Q6: =VLOOKUP($D6,'ip prosedur-14 okt-15 juni 2026'!$A:$H,3, FALSE) -> 58 | R6: =P6*Q6 -> 4220450728 | S6: =VLOOKUP($D6,'ip prosedur-14 okt-15 juni 2026'!$A:$H,5,FALSE) -> 40672345 | T6: =VLOOKUP($D6,'ip prosedur-14 okt-15 juni 2026'!$A:$H,6,FALSE) -> 58786202 | U6: =VLOOKUP($D6,'ip prosedur-14 okt-15 juni 2026'!$A:$H,7,FALSE) -> 91531996 | V6: =VLOOKUP($D6,'ip prosedur-14 okt-15 juni 2026'!$A:$H,8,FALSE) -> 148960900
A7: PDC | B7: P16AB | C7: Stomach, Esophagus & Duodenal Resection Procedures | D7: 43.7 | E7: Partial gastrectomy with anastomosis to jejunum | F7: =VLOOKUP($D7,proc!$A:$D,3, FALSE) -> 6 | G7: =C7 -> Stomach, Esophagus & Duodenal Resection Procedures | H7: =B7 -> P16AB | K7: =VLOOKUP($B7,'tarif idrg'!$A:$O,11,FALSE) -> 18485238 | L7: =VLOOKUP($B7,'tarif idrg'!$A:$O,15,FALSE) -> 18485238 | N7: =IF(C7<>G7,"Change","-") -> - | O7: =VLOOKUP($D7,'ip prosedur-2025'!$A:$H,4,FALSE) -> 74462792 | P7: =VLOOKUP($D7,'ip prosedur-14 okt-15 juni 2026'!$A:$H,4,FALSE) -> 74421012 | Q7: =VLOOKUP($D7,'ip prosedur-14 okt-15 juni 2026'!$A:$H,3, FALSE) -> 231 | R7: =P7*Q7 -> 17191253712 | S7: =VLOOKUP($D7,'ip prosedur-14 okt-15 juni 2026'!$A:$H,5,FALSE) -> 34708610 | T7: =VLOOKUP($D7,'ip prosedur-14 okt-15 juni 2026'!$A:$H,6,FALSE) -> 60993125 | U7: =VLOOKUP($D7,'ip prosedur-14 okt-15 juni 2026'!$A:$H,7,FALSE) -> 92240100 | V7: =VLOOKUP($D7,'ip prosedur-14 okt-15 juni 2026'!$A:$H,8,FALSE) -> 135701622
A8: PDC | B8: P16AB | C8: Stomach, Esophagus & Duodenal Resection Procedures | D8: 43.81 | E8: Partial gastrectomy with jejunal transposition | F8: =VLOOKUP($D8,proc!$A:$D,3, FALSE) -> 6 | G8: =C8 -> Stomach, Esophagus & Duodenal Resection Procedures | H8: =B8 -> P16AB | K8: =VLOOKUP($B8,'tarif idrg'!$A:$O,11,FALSE) -> 18485238 | L8: =VLOOKUP($B8,'tarif idrg'!$A:$O,15,FALSE) -> 18485238 | N8: =IF(C8<>G8,"Change","-") -> - | O8: =VLOOKUP($D8,'ip prosedur-2025'!$A:$H,4,FALSE) -> 80525516 | P8: =VLOOKUP($D8,'ip prosedur-14 okt-15 juni 2026'!$A:$H,4,FALSE) -> 73089081 | Q8: =VLOOKUP($D8,'ip prosedur-14 okt-15 juni 2026'!$A:$H,3, FALSE) -> 5 | R8: =P8*Q8 -> 365445407 | S8: =VLOOKUP($D8,'ip prosedur-14 okt-15 juni 2026'!$A:$H,5,FALSE) -> 63276121 | T8: =VLOOKUP($D8,'ip prosedur-14 okt-15 juni 2026'!$A:$H,6,FALSE) -> 70513922 | U8: =VLOOKUP($D8,'ip prosedur-14 okt-15 juni 2026'!$A:$H,7,FALSE) -> 82309664 | V8: =VLOOKUP($D8,'ip prosedur-14 okt-15 juni 2026'!$A:$H,8,FALSE) -> 104230307
