Workbook

Sheet rajal cluster icd10_web20260922
A1: Cluster Type | B1: Cluster Code | C1: Cluster Description | D1: ICD-10 Code | E1: ICD-10 Description
A2: PDC | B2: D11AA | C2: Nervous system infection | D2: ="A06.6" -> A06.6 | E2: Amoebic brain abscess
A3: PDC | B3: D11AA | C3: Nervous system infection | D3: ="A17.0" -> A17.0 | E3: Tuberculous meningitis
A4: PDC | B4: D11AA | C4: Nervous system infection | D4: ="A17.1" -> A17.1 | E4: Meningeal tuberculoma
A5: PDC | B5: D11AA | C5: Nervous system infection | D5: ="A17.8" -> A17.8 | E5: Other tuberculosis of nervous system
A6: PDC | B6: D11AA | C6: Nervous system infection | D6: ="A17.9" -> A17.9 | E6: Tuberculosis of nervous system unspecified
A7: PDC | B7: D11AA | C7: Nervous system infection | D7: ="A32.1" -> A32.1 | E7: Listerial meningitis and meningoencephalitis
A8: PDC | B8: D11AA | C8: Nervous system infection | D8: ="A39.0" -> A39.0 | E8: Meningococcal meningitis
A9: PDC | B9: D11AA | C9: Nervous system infection | D9: ="A50.4" -> A50.4 | E9: Late congenital neurosyphilis [juvenile neurosyphilis]
A10: PDC | B10: D11AA | C10: Nervous system infection | D10: ="A52.1" -> A52.1 | E10: Symptomatic neurosyphilis
A11: PDC | B11: D11AA | C11: Nervous system infection | D11: ="A52.2" -> A52.2 | E11: Asymptomatic neurosyphilis
A12: PDC | B12: D11AA | C12: Nervous system infection | D12: ="A52.3" -> A52.3 | E12: Neurosyphilis, unspecified
A13: PDC | B13: D11AA | C13: Nervous system infection | D13: ="A80.0" -> A80.0 | E13: Acute paralytic poliomyelitis, vaccine-associated
A14: PDC | B14: D11AA | C14: Nervous system infection | D14: ="A80.1" -> A80.1 | E14: Acute paralytic poliomyelitis, wild virus, imported
A15: PDC | B15: D11AA | C15: Nervous system infection | D15: ="A80.2" -> A80.2 | E15: Acute paralytic poliomyelitis, wild virus, indigenous
A16: PDC | B16: D11AA | C16: Nervous system infection | D16: ="A80.3" -> A80.3 | E16: Acute paralytic poliomyelitis, other and unspecified
A17: PDC | B17: D11AA | C17: Nervous system infection | D17: ="A80.9" -> A80.9 | E17: Acute poliomyelitis, unspecified
A18: PDC | B18: D11AA | C18: Nervous system infection | D18: ="A81.0" -> A81.0 | E18: Creutzfeldt-jakob disease
A19: PDC | B19: D11AA | C19: Nervous system infection | D19: ="A81.1" -> A81.1 | E19: Subacute sclerosing panencephalitis
A20: PDC | B20: D11AA | C20: Nervous system infection | D20: ="A81.2" -> A81.2 | E20: Progressive multifocal leukoencephalopathy
A21: PDC | B21: D11AA | C21: Nervous system infection | D21: ="A81.8" -> A81.8 | E21: Other atypical virus infections of central nervous system
A22: PDC | B22: D11AA | C22: Nervous system infection | D22: ="A81.9" -> A81.9 | E22: Atypical virus infection of central nervous system, unspecified
A23: PDC | B23: D11AA | C23: Nervous system infection | D23: ="A82.0" -> A82.0 | E23: Sylvatic rabies
A24: PDC | B24: D11AA | C24: Nervous system infection | D24: ="A82.1" -> A82.1 | E24: Urban rabies
A25: PDC | B25: D11AA | C25: Nervous system infection | D25: ="A82.9" -> A82.9 | E25: Rabies, unspecified
A26: PDC | B26: D11AA | C26: Nervous system infection | D26: ="A83.0" -> A83.0 | E26: Japanese encephalitis
A27: PDC | B27: D11AA | C27: Nervous system infection | D27: ="A83.1" -> A83.1 | E27: Western equine encephalitis
A28: PDC | B28: D11AA | C28: Nervous system infection | D28: ="A83.2" -> A83.2 | E28: Eastern equine encephalitis
A29: PDC | B29: D11AA | C29: Nervous system infection | D29: ="A83.3" -> A83.3 | E29: St louis encephalitis
A30: PDC | B30: D11AA | C30: Nervous system infection | D30: ="A83.4" -> A83.4 | E30: Australian encephalitis
A31: PDC | B31: D11AA | C31: Nervous system infection | D31: ="A83.5" -> A83.5 | E31: California encephalitis
A32: PDC | B32: D11AA | C32: Nervous system infection | D32: ="A83.6" -> A83.6 | E32: Rocio virus disease
A33: PDC | B33: D11AA | C33: Nervous system infection | D33: ="A83.8" -> A83.8 | E33: Other mosquito-borne viral encephalitis
A34: PDC | B34: D11AA | C34: Nervous system infection | D34: ="A83.9" -> A83.9 | E34: Mosquito-borne viral encephalitis, unspecified
A35: PDC | B35: D11AA | C35: Nervous system infection | D35: ="A84.0" -> A84.0 | E35: Far east tick-born enceph-russn spring-summ enceph
A36: PDC | B36: D11AA | C36: Nervous system infection | D36: ="A84.1" -> A84.1 | E36: Central european tick-borne encephalitis
A37: PDC | B37: D11AA | C37: Nervous system infection | D37: ="A84.8" -> A84.8 | E37: Other tick-borne viral encephalitis
A38: PDC | B38: D11AA | C38: Nervous system infection | D38: ="A84.9" -> A84.9 | E38: Tick-borne viral encephalitis, unspecified
A39: PDC | B39: D11AA | C39: Nervous system infection | D39: ="A85.0" -> A85.0 | E39: Enteroviral encephalitis
A40: PDC | B40: D11AA | C40: Nervous system infection | D40: ="A85.1" -> A85.1 | E40: Adenoviral encephalitis
...

Sheet rajal cluster icd9cm_web2026092
A1: Cluster Type | B1: Cluster Code | C1: Cluster Description | D1: ICD-9-CM Code | E1: ICD-9-CM Description
A2: PDC | B2: P11KC | C2: Extracranial Vessel Proc. | D2: ="88.41" -> 88.41 | E2: Arteriography of cerebral arteries
A3: PDC | B3: P11KA | C3: Other Nervous System Major Proc. | D3: ="01.13" -> 01.13 | E3: Closed [percutaneous] [needle] biopsy of brain
A4: PDC | B4: P11KA | C4: Other Nervous System Major Proc. | D4: ="01.6" -> 01.6 | E4: Excision of lesion of skull
A5: PDC | B5: P11KA | C5: Other Nervous System Major Proc. | D5: ="02.02" -> 02.02 | E5: Elevation of skull fracture fragments
A6: PDC | B6: P11KA | C6: Other Nervous System Major Proc. | D6: ="02.41" -> 02.41 | E6: Irrigation and exploration of ventricular shunt
A7: PDC | B7: P11KA | C7: Other Nervous System Major Proc. | D7: ="02.43" -> 02.43 | E7: Removal of ventricular shunt
A8: PDC | B8: P11KA | C8: Other Nervous System Major Proc. | D8: ="02.96" -> 02.96 | E8: Insertion of sphenoidal electrodes
A9: PDC | B9: P11KA | C9: Other Nervous System Major Proc. | D9: ="03.21" -> 03.21 | E9: Percutaneous chordotomy
A10: PDC | B10: P11KA | C10: Other Nervous System Major Proc. | D10: ="03.32" -> 03.32 | E10: Biopsy of spinal cord or spinal meninges
A11: PDC | B11: P11KA | C11: Other Nervous System Major Proc. | D11: ="03.94" -> 03.94 | E11: Removal of spinal neurostimulator lead(s)
A12: PDC | B12: P11KA | C12: Other Nervous System Major Proc. | D12: ="03.99" -> 03.99 | E12: Other operations on spinal cord and spinal canal structures
A13: PDC | B13: P11KA | C13: Other Nervous System Major Proc. | D13: ="04.05" -> 04.05 | E13: Gasserian ganglionectomy
A14: PDC | B14: P11KA | C14: Other Nervous System Major Proc. | D14: ="04.06" -> 04.06 | E14: Other cranial or peripheral ganglionectomy
A15: PDC | B15: P11KA | C15: Other Nervous System Major Proc. | D15: ="04.07" -> 04.07 | E15: Other excision or avulsion of cranial and peripheral nerves
A16: PDC | B16: P11KA | C16: Other Nervous System Major Proc. | D16: ="04.3" -> 04.3 | E16: Suture of cranial and peripheral nerves
A17: PDC | B17: P11KA | C17: Other Nervous System Major Proc. | D17: ="04.42" -> 04.42 | E17: Other cranial nerve decompression
A18: PDC | B18: P11KA | C18: Other Nervous System Major Proc. | D18: ="04.49" -> 04.49 | E18: Other peripheral nerve or ganglion decompression or lysis of adhesions
A19: PDC | B19: P11KD | C19: Release of Carpal/Tarsal Tunnel | D19: ="04.43" -> 04.43 | E19: Release of carpal tunnel
A20: PDC | B20: P11KD | C20: Release of Carpal/Tarsal Tunnel | D20: ="04.44" -> 04.44 | E20: Release of tarsal tunnel
A21: PDC | B21: P11KP | C21: Other Nervous System Minor Proc. | D21: ="01.01" -> 01.01 | E21: Cisternal puncture
A22: PDC | B22: P11KP | C22: Other Nervous System Minor Proc. | D22: ="01.09" -> 01.09 | E22: Other cranial puncture
A23: PDC | B23: P11KP | C23: Other Nervous System Minor Proc. | D23: ="01.11" -> 01.11 | E23: Closed [percutaneous] [needle] biopsy of cerebral meninges
A24: PDC | B24: P11KP | C24: Other Nervous System Minor Proc. | D24: ="03.8" -> 03.8 | E24: Injection of destructive agent into spinal canal
A25: PDC | B25: P11KP | C25: Other Nervous System Minor Proc. | D25: ="03.90" -> 03.90 | E25: Insertion of catheter into spinal canal for infusion of therapeutic or palliative substances
A26: PDC | B26: P11KP | C26: Other Nervous System Minor Proc. | D26: ="03.91" -> 03.91 | E26: Injection of anesthetic into spinal canal for analgesia
A27: PDC | B27: P11KP | C27: Other Nervous System Minor Proc. | D27: ="03.92" -> 03.92 | E27: Injection of other agent into spinal canal
A28: PDC | B28: P11KP | C28: Other Nervous System Minor Proc. | D28: ="03.95" -> 03.95 | E28: Spinal blood patch
A29: PDC | B29: P11KP | C29: Other Nervous System Minor Proc. | D29: ="04.11" -> 04.11 | E29: Closed [percutaneous] [needle] biopsy of cranial or peripheral nerve or ganglion
A30: PDC | B30: P11KP | C30: Other Nervous System Minor Proc. | D30: ="04.91" -> 04.91 | E30: Neurectasis
A31: PDC | B31: P11KP | C31: Other Nervous System Minor Proc. | D31: ="04.99" -> 04.99 | E31: Other operations on cranial and peripheral nerves
A32: PDC | B32: P11KP | C32: Other Nervous System Minor Proc. | D32: ="05.0" -> 05.0 | E32: Division of sympathetic nerve or ganglion
A33: PDC | B33: P11KP | C33: Other Nervous System Minor Proc. | D33: ="05.11" -> 05.11 | E33: Biopsy of sympathetic nerve or ganglion
A34: PDC | B34: P11KP | C34: Other Nervous System Minor Proc. | D34: ="05.9" -> 05.9 | E34: Other operations on nervous system
A35: PDC | B35: P11KP | C35: Other Nervous System Minor Proc. | D35: ="83.91" -> 83.91 | E35: Lysis of adhesions of muscle, tendon, fascia, and bursa
A36: PDC | B36: P11KP | C36: Other Nervous System Minor Proc. | D36: ="86.22" -> 86.22 | E36: Excisional debridement of wound, infection, or burn
A37: PDC | B37: P11KP | C37: Other Nervous System Minor Proc. | D37: ="94.28" -> 94.28 | E37: Transcranial magnetic stimulation (TMS) (IM)
A38: PDC | B38: P11KF | C38: Nervous System Other Diagnostic Proc. | D38: ="01.18" -> 01.18 | E38: Other diagnostic procedures on brain and cerebral meninges
A39: PDC | B39: P11KF | C39: Nervous System Other Diagnostic Proc. | D39: ="03.31" -> 03.31 | E39: Spinal tap
A40: PDC | B40: P11KF | C40: Nervous System Other Diagnostic Proc. | D40: ="03.39" -> 03.39 | E40: Other diagnostic procedures on spinal cord and spinal canal structures
...

Sheet ranap cluster icd10_web20260922
A1: Cluster Type | B1: Cluster Code | C1: Cluster Description | D1: ICD-10 Code | E1: ICD-10 Description
A2: PDC | B2: D11AA | C2: Nervous system infection | D2: ="A06.6" -> A06.6 | E2: Amoebic brain abscess
A3: PDC | B3: D11AA | C3: Nervous system infection | D3: ="A17.0" -> A17.0 | E3: Tuberculous meningitis
A4: PDC | B4: D11AA | C4: Nervous system infection | D4: ="A17.1" -> A17.1 | E4: Meningeal tuberculoma
A5: PDC | B5: D11AA | C5: Nervous system infection | D5: ="A17.8" -> A17.8 | E5: Other tuberculosis of nervous system
A6: PDC | B6: D11AA | C6: Nervous system infection | D6: ="A17.9" -> A17.9 | E6: Tuberculosis of nervous system unspecified
A7: PDC | B7: D11AA | C7: Nervous system infection | D7: ="A32.1" -> A32.1 | E7: Listerial meningitis and meningoencephalitis
A8: PDC | B8: D11AA | C8: Nervous system infection | D8: ="A39.0" -> A39.0 | E8: Meningococcal meningitis
A9: PDC | B9: D11AA | C9: Nervous system infection | D9: ="A50.4" -> A50.4 | E9: Late congenital neurosyphilis [juvenile neurosyphilis]
A10: PDC | B10: D11AA | C10: Nervous system infection | D10: ="A52.1" -> A52.1 | E10: Symptomatic neurosyphilis
A11: PDC | B11: D11AA | C11: Nervous system infection | D11: ="A52.2" -> A52.2 | E11: Asymptomatic neurosyphilis
A12: PDC | B12: D11AA | C12: Nervous system infection | D12: ="A52.3" -> A52.3 | E12: Neurosyphilis, unspecified
A13: PDC | B13: D11AA | C13: Nervous system infection | D13: ="A80.0" -> A80.0 | E13: Acute paralytic poliomyelitis, vaccine-associated
A14: PDC | B14: D11AA | C14: Nervous system infection | D14: ="A80.1" -> A80.1 | E14: Acute paralytic poliomyelitis, wild virus, imported
A15: PDC | B15: D11AA | C15: Nervous system infection | D15: ="A80.2" -> A80.2 | E15: Acute paralytic poliomyelitis, wild virus, indigenous
A16: PDC | B16: D11AA | C16: Nervous system infection | D16: ="A80.3" -> A80.3 | E16: Acute paralytic poliomyelitis, other and unspecified
A17: PDC | B17: D11AA | C17: Nervous system infection | D17: ="A80.9" -> A80.9 | E17: Acute poliomyelitis, unspecified
A18: PDC | B18: D11AA | C18: Nervous system infection | D18: ="A81.0" -> A81.0 | E18: Creutzfeldt-jakob disease
A19: PDC | B19: D11AA | C19: Nervous system infection | D19: ="A81.1" -> A81.1 | E19: Subacute sclerosing panencephalitis
A20: PDC | B20: D11AA | C20: Nervous system infection | D20: ="A81.2" -> A81.2 | E20: Progressive multifocal leukoencephalopathy
A21: PDC | B21: D11AA | C21: Nervous system infection | D21: ="A81.8" -> A81.8 | E21: Other atypical virus infections of central nervous system
A22: PDC | B22: D11AA | C22: Nervous system infection | D22: ="A81.9" -> A81.9 | E22: Atypical virus infection of central nervous system, unspecified
A23: PDC | B23: D11AA | C23: Nervous system infection | D23: ="A82.0" -> A82.0 | E23: Sylvatic rabies
A24: PDC | B24: D11AA | C24: Nervous system infection | D24: ="A82.1" -> A82.1 | E24: Urban rabies
A25: PDC | B25: D11AA | C25: Nervous system infection | D25: ="A82.9" -> A82.9 | E25: Rabies, unspecified
A26: PDC | B26: D11AA | C26: Nervous system infection | D26: ="A83.0" -> A83.0 | E26: Japanese encephalitis
A27: PDC | B27: D11AA | C27: Nervous system infection | D27: ="A83.1" -> A83.1 | E27: Western equine encephalitis
A28: PDC | B28: D11AA | C28: Nervous system infection | D28: ="A83.2" -> A83.2 | E28: Eastern equine encephalitis
A29: PDC | B29: D11AA | C29: Nervous system infection | D29: ="A83.3" -> A83.3 | E29: St louis encephalitis
A30: PDC | B30: D11AA | C30: Nervous system infection | D30: ="A83.4" -> A83.4 | E30: Australian encephalitis
A31: PDC | B31: D11AA | C31: Nervous system infection | D31: ="A83.5" -> A83.5 | E31: California encephalitis
A32: PDC | B32: D11AA | C32: Nervous system infection | D32: ="A83.6" -> A83.6 | E32: Rocio virus disease
A33: PDC | B33: D11AA | C33: Nervous system infection | D33: ="A83.8" -> A83.8 | E33: Other mosquito-borne viral encephalitis
A34: PDC | B34: D11AA | C34: Nervous system infection | D34: ="A83.9" -> A83.9 | E34: Mosquito-borne viral encephalitis, unspecified
A35: PDC | B35: D11AA | C35: Nervous system infection | D35: ="A84.0" -> A84.0 | E35: Far east tick-born enceph-russn spring-summ enceph
A36: PDC | B36: D11AA | C36: Nervous system infection | D36: ="A84.1" -> A84.1 | E36: Central european tick-borne encephalitis
A37: PDC | B37: D11AA | C37: Nervous system infection | D37: ="A84.8" -> A84.8 | E37: Other tick-borne viral encephalitis
A38: PDC | B38: D11AA | C38: Nervous system infection | D38: ="A84.9" -> A84.9 | E38: Tick-borne viral encephalitis, unspecified
A39: PDC | B39: D11AA | C39: Nervous system infection | D39: ="A85.0" -> A85.0 | E39: Enteroviral encephalitis
A40: PDC | B40: D11AA | C40: Nervous system infection | D40: ="A85.1" -> A85.1 | E40: Adenoviral encephalitis
...

Sheet ranap cluster icd9cm_web2026092
A1: Cluster Type | B1: Cluster Code | C1: Cluster Description | D1: ICD-9-CM Code | E1: ICD-9-CM Description
A2: PDC | B2: P11AA | C2: Endovascular Procedures for Neurologic Diseases | D2: ="00.62" -> 00.62 | E2: Percutaneous angioplasty or atherectomy of intracranial vessel(s)
A3: PDC | B3: P11AA | C3: Endovascular Procedures for Neurologic Diseases | D3: ="38.52" -> 38.52 | E3: Ligation and stripping of varicose veins, other vessels of head and neck
A4: PDC | B4: P11AA | C4: Endovascular Procedures for Neurologic Diseases | D4: ="38.7" -> 38.7 | E4: Interruption vena cava
A5: PDC | B5: P11AA | C5: Endovascular Procedures for Neurologic Diseases | D5: ="38.82" -> 38.82 | E5: Other surgical occlusion of vessels, other vessels of head and neck
A6: PDC | B6: P11AA | C6: Endovascular Procedures for Neurologic Diseases | D6: ="39.72" -> 39.72 | E6: Endovascular embolization or occlusion of head and neck vessels
A7: PDC | B7: P11AA | C7: Endovascular Procedures for Neurologic Diseases | D7: ="39.74" -> 39.74 | E7: Endovascular removal of obstruction from head and neck vessel(s)
A8: PDC | B8: P11AA | C8: Endovascular Procedures for Neurologic Diseases | D8: ="39.75" -> 39.75 | E8: Endovascular embolization or occlusion of vessel(s) of head or neck using bare coils
A9: PDC | B9: P11AA | C9: Endovascular Procedures for Neurologic Diseases | D9: ="39.76" -> 39.76 | E9: Endovascular embolization or occlusion of vessel(s) of head or neck using bioactive coils
A10: PDC | B10: P11AA | C10: Endovascular Procedures for Neurologic Diseases | D10: ="39.81" -> 39.81 | E10: Implantation or replacement of carotid sinus stimulation device, total system (IM)
A11: PDC | B11: P11AA | C11: Endovascular Procedures for Neurologic Diseases | D11: ="39.82" -> 39.82 | E11: Implantation or replacement of carotid sinus stimulation lead(s) only (IM)
A12: PDC | B12: P11AA | C12: Endovascular Procedures for Neurologic Diseases | D12: ="39.83" -> 39.83 | E12: Implantation or replacement of carotid sinus stimulation pulse generator only (IM)
A13: PDC | B13: P11AA | C13: Endovascular Procedures for Neurologic Diseases | D13: ="39.84" -> 39.84 | E13: Revision of carotid sinus stimulation lead(s) only (IM)
A14: PDC | B14: P11AA | C14: Endovascular Procedures for Neurologic Diseases | D14: ="39.85" -> 39.85 | E14: Revision of carotid sinus stimulation pulse generator (IM)
A15: PDC | B15: P11AA | C15: Endovascular Procedures for Neurologic Diseases | D15: ="39.86" -> 39.86 | E15: Removal of carotid sinus stimulation device, total system (IM)
A16: PDC | B16: P11AA | C16: Endovascular Procedures for Neurologic Diseases | D16: ="39.87" -> 39.87 | E16: Removal of carotid sinus stimulation lead(s) only (IM)
A17: PDC | B17: P11AA | C17: Endovascular Procedures for Neurologic Diseases | D17: ="39.88" -> 39.88 | E17: Removal of carotid sinus stimulation pulse generator only (IM)
A18: PDC | B18: P11AA | C18: Endovascular Procedures for Neurologic Diseases | D18: ="39.89" -> 39.89 | E18: Other operations on carotid body, carotid sinus and other vascular bodies (IM)
A19: PDC | B19: P11AB | C19: Complex Spinal Procedures | D19: ="03.4" -> 03.4 | E19: Excision or destruction of lesion of spinal cord or spinal meninges
A20: PDC | B20: P11AB | C20: Complex Spinal Procedures | D20: ="03.52" -> 03.52 | E20: Repair of spinal myelomeningocele
A21: PDC | B21: P11AB | C21: Complex Spinal Procedures | D21: ="03.99" -> 03.99 | E21: Other operations on spinal cord and spinal canal structures
A22: PDC | B22: P11AB | C22: Complex Spinal Procedures | D22: ="81.00" -> 81.00 | E22: Spinal fusion, not otherwise specified
A23: PDC | B23: P11AB | C23: Complex Spinal Procedures | D23: ="81.01" -> 81.01 | E23: Atlas-axis spinal fusion
A24: PDC | B24: P11AB | C24: Complex Spinal Procedures | D24: ="81.02" -> 81.02 | E24: Other cervical fusion of the anterior column, anterior technique
A25: PDC | B25: P11AB | C25: Complex Spinal Procedures | D25: ="81.03" -> 81.03 | E25: Other cervical fusion of the posterior column, posterior technique
A26: PDC | B26: P11AB | C26: Complex Spinal Procedures | D26: ="81.04" -> 81.04 | E26: Dorsal and dorsolumbar fusion of the anterior column, anterior technique
A27: PDC | B27: P11AB | C27: Complex Spinal Procedures | D27: ="81.05" -> 81.05 | E27: Dorsal and dorsolumbar fusion of the posterior column, posterior technique
A28: PDC | B28: P11AB | C28: Complex Spinal Procedures | D28: ="81.06" -> 81.06 | E28: Lumbar and lumbosacral fusion of the anterior column, anterior technique
A29: PDC | B29: P11AB | C29: Complex Spinal Procedures | D29: ="81.07" -> 81.07 | E29: Lumbar and lumbosacral fusion of the posterior column, posterior technique
A30: PDC | B30: P11AB | C30: Complex Spinal Procedures | D30: ="81.08" -> 81.08 | E30: Lumbar and lumbosacral fusion of the anterior column, posterior technique
A31: PDC | B31: P11AB | C31: Complex Spinal Procedures | D31: ="81.30" -> 81.30 | E31: Refusion of spine, not otherwise specified
A32: PDC | B32: P11AB | C32: Complex Spinal Procedures | D32: ="81.31" -> 81.31 | E32: Refusion of atlas-axis spine
A33: PDC | B33: P11AB | C33: Complex Spinal Procedures | D33: ="81.32" -> 81.32 | E33: Refusion of other cervical spine, anterior column, anterior technique
A34: PDC | B34: P11AB | C34: Complex Spinal Procedures | D34: ="81.33" -> 81.33 | E34: Refusion of other cervical spine, posterior column, posterior technique
A35: PDC | B35: P11AB | C35: Complex Spinal Procedures | D35: ="81.34" -> 81.34 | E35: Refusion of dorsal and dorsolumbar spine, anterior column, anterior technique
A36: PDC | B36: P11AB | C36: Complex Spinal Procedures | D36: ="81.35" -> 81.35 | E36: Refusion of dorsal and dorsolumbar spine, posterior column, posterior technique
A37: PDC | B37: P11AB | C37: Complex Spinal Procedures | D37: ="81.36" -> 81.36 | E37: Refusion of lumbar and lumbosacral spine, anterior column, anterior technique
A38: PDC | B38: P11AB | C38: Complex Spinal Procedures | D38: ="81.37" -> 81.37 | E38: Refusion of lumbar and lumbosacral spine, posterior column, posterior technique
A39: PDC | B39: P11AB | C39: Complex Spinal Procedures | D39: ="81.38" -> 81.38 | E39: Refusion of lumbar and lumbosacral spine, anterior column, posterior technique
A40: PDC | B40: P11AB | C40: Complex Spinal Procedures | D40: ="81.39" -> 81.39 | E40: Refusion of spine, not elsewhere classified
...

Sheet ranap clusters obsolete
A1: Cluster Type | B1: Cluster Code | C1: Cluster Description | D1: ICD-9-CM Code | E1: ICD-9-CM Description | F1: Grade | G1: IM | H1: New Cluster Description | I1: new PDC | J1: jumlah kasus | K1: mean_billing | L1: p25 | M1: p50 | N1: p75 | O1: p90 | P1: total | Q1: Keterangan | R1: 8037060
A2: PDC | B2: P11AC | C2: Endovascular Procedures for Neurologic Diseases | D2: 00.62 | E2: Percutaneous angioplasty or atherectomy of intracranial vessel(s) | F2: =VLOOKUP($D2,proc!$A:$D,3,FALSE) -> 3 | G2: =VLOOKUP($D2,proc!$A:$D,4,FALSE) -> 0 | H2: Endovascular Proc. for Neurologic Diseases | J2: =VLOOKUP($D2,'prosedur-2025'!$A:$H,3,FALSE) -> 120 | K2: =VLOOKUP($D2,'prosedur-2025'!$A:$H,4,FALSE) -> 78497963 | L2: =VLOOKUP($D2,'prosedur-2025'!$A:$H,5,FALSE) -> 31029390 | M2: =VLOOKUP($D2,'prosedur-2025'!$A:$H,6,FALSE) -> 49040723 | N2: =VLOOKUP($D2,'prosedur-2025'!$A:$H,7,FALSE) -> 88993193 | O2: =VLOOKUP($D2,'prosedur-2025'!$A:$H,8,FALSE) -> 153022000 | P2: =J2*K2 -> 9419755502
A3: PDC | B3: P11AC | C3: Endovascular Procedures for Neurologic Diseases | D3: 38.52 | E3: Ligation and stripping of varicose veins, other vessels of head and neck | F3: =VLOOKUP($D3,proc!$A:$D,3,FALSE) -> 0 | G3: =VLOOKUP($D3,proc!$A:$D,4,FALSE) -> 0 | H3: Endovascular Proc. for Neurologic Diseases | J3: =VLOOKUP($D3,'prosedur-2025'!$A:$H,3,FALSE) -> 33 | K3: =VLOOKUP($D3,'prosedur-2025'!$A:$H,4,FALSE) -> 21821658 | L3: =VLOOKUP($D3,'prosedur-2025'!$A:$H,5,FALSE) -> 7330331 | M3: =VLOOKUP($D3,'prosedur-2025'!$A:$H,6,FALSE) -> 13625695 | N3: =VLOOKUP($D3,'prosedur-2025'!$A:$H,7,FALSE) -> 22771045 | O3: =VLOOKUP($D3,'prosedur-2025'!$A:$H,8,FALSE) -> 55892400 | P3: =J3*K3 -> 720114702
A4: PDC | B4: P11AC | C4: Endovascular Procedures for Neurologic Diseases | D4: 38.7 | E4: Interruption vena cava | F4: =VLOOKUP($D4,proc!$A:$D,3,FALSE) -> 5 | G4: =VLOOKUP($D4,proc!$A:$D,4,FALSE) -> 0 | H4: Endovascular Proc. for Neurologic Diseases | J4: =VLOOKUP($D4,'prosedur-2025'!$A:$H,3,FALSE) -> 121 | K4: =VLOOKUP($D4,'prosedur-2025'!$A:$H,4,FALSE) -> 67670327 | L4: =VLOOKUP($D4,'prosedur-2025'!$A:$H,5,FALSE) -> 29852859 | M4: =VLOOKUP($D4,'prosedur-2025'!$A:$H,6,FALSE) -> 58105112 | N4: =VLOOKUP($D4,'prosedur-2025'!$A:$H,7,FALSE) -> 92598541 | O4: =VLOOKUP($D4,'prosedur-2025'!$A:$H,8,FALSE) -> 135912123 | P4: =J4*K4 -> 8188109584
A5: PDC | B5: P11AC | C5: Endovascular Procedures for Neurologic Diseases | D5: 38.82 | E5: Other surgical occlusion of vessels, other vessels of head and neck | F5: =VLOOKUP($D5,proc!$A:$D,3,FALSE) -> 4 | G5: =VLOOKUP($D5,proc!$A:$D,4,FALSE) -> 0 | H5: Endovascular Proc. for Neurologic Diseases | J5: =VLOOKUP($D5,'prosedur-2025'!$A:$H,3,FALSE) -> 434 | K5: =VLOOKUP($D5,'prosedur-2025'!$A:$H,4,FALSE) -> 48032893 | L5: =VLOOKUP($D5,'prosedur-2025'!$A:$H,5,FALSE) -> 10435277 | M5: =VLOOKUP($D5,'prosedur-2025'!$A:$H,6,FALSE) -> 22179491 | N5: =VLOOKUP($D5,'prosedur-2025'!$A:$H,7,FALSE) -> 61098522 | O5: =VLOOKUP($D5,'prosedur-2025'!$A:$H,8,FALSE) -> 123946351 | P5: =J5*K5 -> 20846275429
A6: PDC | B6: P11AC | C6: Endovascular Procedures for Neurologic Diseases | D6: 39.72 | E6: Endovascular embolization or occlusion of head and neck vessels | F6: =VLOOKUP($D6,proc!$A:$D,3,FALSE) -> 6 | G6: =VLOOKUP($D6,proc!$A:$D,4,FALSE) -> 0 | H6: Endovascular Proc. for Neurologic Diseases | J6: =VLOOKUP($D6,'prosedur-2025'!$A:$H,3,FALSE) -> 339 | K6: =VLOOKUP($D6,'prosedur-2025'!$A:$H,4,FALSE) -> 77422054 | L6: =VLOOKUP($D6,'prosedur-2025'!$A:$H,5,FALSE) -> 34528674 | M6: =VLOOKUP($D6,'prosedur-2025'!$A:$H,6,FALSE) -> 59125877 | N6: =VLOOKUP($D6,'prosedur-2025'!$A:$H,7,FALSE) -> 99036851 | O6: =VLOOKUP($D6,'prosedur-2025'!$A:$H,8,FALSE) -> 162366954 | P6: =J6*K6 -> 26246076412
A7: PDC | B7: P11AC | C7: Endovascular Procedures for Neurologic Diseases | D7: 39.74 | E7: Endovascular removal of obstruction from head and neck vessel(s) | F7: =VLOOKUP($D7,proc!$A:$D,3,FALSE) -> 5 | G7: =VLOOKUP($D7,proc!$A:$D,4,FALSE) -> 0 | H7: Endovascular Proc. for Neurologic Diseases | J7: =VLOOKUP($D7,'prosedur-2025'!$A:$H,3,FALSE) -> 412 | K7: =VLOOKUP($D7,'prosedur-2025'!$A:$H,4,FALSE) -> 1.1316846e+08 | L7: =VLOOKUP($D7,'prosedur-2025'!$A:$H,5,FALSE) -> 61273050 | M7: =VLOOKUP($D7,'prosedur-2025'!$A:$H,6,FALSE) -> 97611950 | N7: =VLOOKUP($D7,'prosedur-2025'!$A:$H,7,FALSE) -> 139420700 | O7: =VLOOKUP($D7,'prosedur-2025'!$A:$H,8,FALSE) -> 193880000 | P7: =J7*K7 -> 46625405734
A8: PDC | B8: P11AC | C8: Endovascular Procedures for Neurologic Diseases | D8: 39.75 | E8: Endovascular embolization or occlusion of vessel(s) of head or neck using bare coils | F8: =VLOOKUP($D8,proc!$A:$D,3,FALSE) -> 5 | G8: =VLOOKUP($D8,proc!$A:$D,4,FALSE) -> 0 | H8: Endovascular Proc. for Neurologic Diseases | J8: =VLOOKUP($D8,'prosedur-2025'!$A:$H,3,FALSE) -> 820 | K8: =VLOOKUP($D8,'prosedur-2025'!$A:$H,4,FALSE) -> 1.2139781e+08 | L8: =VLOOKUP($D8,'prosedur-2025'!$A:$H,5,FALSE) -> 72539060 | M8: =VLOOKUP($D8,'prosedur-2025'!$A:$H,6,FALSE) -> 100933007 | N8: =VLOOKUP($D8,'prosedur-2025'!$A:$H,7,FALSE) -> 144954100 | O8: =VLOOKUP($D8,'prosedur-2025'!$A:$H,8,FALSE) -> 207161425 | P8: =J8*K8 -> 99546207534
A9: PDC | B9: P11AC | C9: Endovascular Procedures for Neurologic Diseases | D9: 39.76 | E9: Endovascular embolization or occlusion of vessel(s) of head or neck using bioactive coils | F9: =VLOOKUP($D9,proc!$A:$D,3,FALSE) -> 5 | G9: =VLOOKUP($D9,proc!$A:$D,4,FALSE) -> 0 | H9: Endovascular Proc. for Neurologic Diseases | J9: =VLOOKUP($D9,'prosedur-2025'!$A:$H,3,FALSE) -> 25 | K9: =VLOOKUP($D9,'prosedur-2025'!$A:$H,4,FALSE) -> 73873294 | L9: =VLOOKUP($D9,'prosedur-2025'!$A:$H,5,FALSE) -> 46871484 | M9: =VLOOKUP($D9,'prosedur-2025'!$A:$H,6,FALSE) -> 62436689 | N9: =VLOOKUP($D9,'prosedur-2025'!$A:$H,7,FALSE) -> 95671460 | O9: =VLOOKUP($D9,'prosedur-2025'!$A:$H,8,FALSE) -> 147131046 | P9: =J9*K9 -> 1846832339
A10: PDC | B10: P11AC | C10: Endovascular Procedures for Neurologic Diseases | D10: 39.81 | E10: Implantation or replacement of carotid sinus stimulation device, total system (IM) | F10: =VLOOKUP($D10,proc!$A:$D,3,FALSE) -> 4 | G10: =VLOOKUP($D10,proc!$A:$D,4,FALSE) -> 1 | H10: Endovascular Proc. for Neurologic Diseases | J10: =VLOOKUP($D10,'prosedur-2025'!$A:$H,3,FALSE) -> 3 | K10: =VLOOKUP($D10,'prosedur-2025'!$A:$H,4,FALSE) -> 66396559 | L10: =VLOOKUP($D10,'prosedur-2025'!$A:$H,5,FALSE) -> 13113019 | M10: =VLOOKUP($D10,'prosedur-2025'!$A:$H,6,FALSE) -> 55660455 | N10: =VLOOKUP($D10,'prosedur-2025'!$A:$H,7,FALSE) -> 130416204 | O10: =VLOOKUP($D10,'prosedur-2025'!$A:$H,8,FALSE) -> 130416204 | P10: =J10*K10 -> 199189678
A11: PDC | B11: P11AC | C11: Endovascular Procedures for Neurologic Diseases | D11: 39.82 | E11: Implantation or replacement of carotid sinus stimulation lead(s) only (IM) | F11: =VLOOKUP($D11,proc!$A:$D,3,FALSE) -> 4 | G11: =VLOOKUP($D11,proc!$A:$D,4,FALSE) -> 1 | H11: Endovascular Proc. for Neurologic Diseases | J11: =VLOOKUP($D11,'prosedur-2025'!$A:$H,3,FALSE) -> 3 | K11: =VLOOKUP($D11,'prosedur-2025'!$A:$H,4,FALSE) -> 22003947 | L11: =VLOOKUP($D11,'prosedur-2025'!$A:$H,5,FALSE) -> 2830922 | M11: =VLOOKUP($D11,'prosedur-2025'!$A:$H,6,FALSE) -> 23146200 | N11: =VLOOKUP($D11,'prosedur-2025'!$A:$H,7,FALSE) -> 40034720 | O11: =VLOOKUP($D11,'prosedur-2025'!$A:$H,8,FALSE) -> 40034720 | P11: =J11*K11 -> 66011842
A12: PDC | B12: P11AC | C12: Endovascular Procedures for Neurologic Diseases | D12: 39.83 | E12: Implantation or replacement of carotid sinus stimulation pulse generator only (IM) | F12: =VLOOKUP($D12,proc!$A:$D,3,FALSE) -> 4 | G12: =VLOOKUP($D12,proc!$A:$D,4,FALSE) -> 1 | H12: Endovascular Proc. for Neurologic Diseases | J12: =VLOOKUP($D12,'prosedur-2025'!$A:$H,3,FALSE) -> 21 | K12: =VLOOKUP($D12,'prosedur-2025'!$A:$H,4,FALSE) -> 61165163 | L12: =VLOOKUP($D12,'prosedur-2025'!$A:$H,5,FALSE) -> 24235442 | M12: =VLOOKUP($D12,'prosedur-2025'!$A:$H,6,FALSE) -> 50697300 | N12: =VLOOKUP($D12,'prosedur-2025'!$A:$H,7,FALSE) -> 81533763 | O12: =VLOOKUP($D12,'prosedur-2025'!$A:$H,8,FALSE) -> 143177942 | P12: =J12*K12 -> 1284468416
A13: PDC | B13: P11AC | C13: Endovascular Procedures for Neurologic Diseases | D13: 39.84 | E13: Revision of carotid sinus stimulation lead(s) only (IM) | F13: =VLOOKUP($D13,proc!$A:$D,3,FALSE) -> 4 | G13: =VLOOKUP($D13,proc!$A:$D,4,FALSE) -> 1 | H13: Endovascular Proc. for Neurologic Diseases
A14: PDC | B14: P11AC | C14: Endovascular Procedures for Neurologic Diseases | D14: 39.85 | E14: Revision of carotid sinus stimulation pulse generator (IM) | F14: =VLOOKUP($D14,proc!$A:$D,3,FALSE) -> 4 | G14: =VLOOKUP($D14,proc!$A:$D,4,FALSE) -> 1 | H14: Endovascular Proc. for Neurologic Diseases | J14: =VLOOKUP($D14,'prosedur-2025'!$A:$H,3,FALSE) -> 19 | K14: =VLOOKUP($D14,'prosedur-2025'!$A:$H,4,FALSE) -> 33694355 | L14: =VLOOKUP($D14,'prosedur-2025'!$A:$H,5,FALSE) -> 11539385 | M14: =VLOOKUP($D14,'prosedur-2025'!$A:$H,6,FALSE) -> 17995946 | N14: =VLOOKUP($D14,'prosedur-2025'!$A:$H,7,FALSE) -> 46867900 | O14: =VLOOKUP($D14,'prosedur-2025'!$A:$H,8,FALSE) -> 106980599 | P14: =J14*K14 -> 640192748
A15: PDC | B15: P11AC | C15: Endovascular Procedures for Neurologic Diseases | D15: 39.86 | E15: Removal of carotid sinus stimulation device, total system (IM) | F15: =VLOOKUP($D15,proc!$A:$D,3,FALSE) -> 4 | G15: =VLOOKUP($D15,proc!$A:$D,4,FALSE) -> 1 | H15: Endovascular Proc. for Neurologic Diseases
A16: PDC | B16: P11AC | C16: Endovascular Procedures for Neurologic Diseases | D16: 39.87 | E16: Removal of carotid sinus stimulation lead(s) only (IM) | F16: =VLOOKUP($D16,proc!$A:$D,3,FALSE) -> 4 | G16: =VLOOKUP($D16,proc!$A:$D,4,FALSE) -> 1 | H16: Endovascular Proc. for Neurologic Diseases | J16: =VLOOKUP($D16,'prosedur-2025'!$A:$H,3,FALSE) -> 9 | K16: =VLOOKUP($D16,'prosedur-2025'!$A:$H,4,FALSE) -> 45263476 | L16: =VLOOKUP($D16,'prosedur-2025'!$A:$H,5,FALSE) -> 12766300 | M16: =VLOOKUP($D16,'prosedur-2025'!$A:$H,6,FALSE) -> 27068225 | N16: =VLOOKUP($D16,'prosedur-2025'!$A:$H,7,FALSE) -> 76887394 | O16: =VLOOKUP($D16,'prosedur-2025'!$A:$H,8,FALSE) -> 113466738 | P16: =J16*K16 -> 407371283
A17: PDC | B17: P11AC | C17: Endovascular Procedures for Neurologic Diseases | D17: 39.88 | E17: Removal of carotid sinus stimulation pulse generator only (IM) | F17: =VLOOKUP($D17,proc!$A:$D,3,FALSE) -> 4 | G17: =VLOOKUP($D17,proc!$A:$D,4,FALSE) -> 1 | H17: Endovascular Proc. for Neurologic Diseases | J17: =VLOOKUP($D17,'prosedur-2025'!$A:$H,3,FALSE) -> 4 | K17: =VLOOKUP($D17,'prosedur-2025'!$A:$H,4,FALSE) -> 80759175 | L17: =VLOOKUP($D17,'prosedur-2025'!$A:$H,5,FALSE) -> 27335689 | M17: =VLOOKUP($D17,'prosedur-2025'!$A:$H,6,FALSE) -> 59070224 | N17: =VLOOKUP($D17,'prosedur-2025'!$A:$H,7,FALSE) -> 62839575 | O17: =VLOOKUP($D17,'prosedur-2025'!$A:$H,8,FALSE) -> 173791213 | P17: =J17*K17 -> 323036701
A18: PDC | B18: P11AC | C18: Endovascular Procedures for Neurologic Diseases | D18: 39.89 | E18: Other operations on carotid body, carotid sinus and other vascular bodies (IM) | F18: =VLOOKUP($D18,proc!$A:$D,3,FALSE) -> 4 | G18: =VLOOKUP($D18,proc!$A:$D,4,FALSE) -> 1 | H18: Endovascular Proc. for Neurologic Diseases | J18: =VLOOKUP($D18,'prosedur-2025'!$A:$H,3,FALSE) -> 6 | K18: =VLOOKUP($D18,'prosedur-2025'!$A:$H,4,FALSE) -> 30687575 | L18: =VLOOKUP($D18,'prosedur-2025'!$A:$H,5,FALSE) -> 8104487 | M18: =VLOOKUP($D18,'prosedur-2025'!$A:$H,6,FALSE) -> 27889516 | N18: =VLOOKUP($D18,'prosedur-2025'!$A:$H,7,FALSE) -> 34947067 | O18: =VLOOKUP($D18,'prosedur-2025'!$A:$H,8,FALSE) -> 76434965 | P18: =J18*K18 -> 184125448
A19: PDC | B19: P11AD | C19: Complex Spinal Procedures | D19: 03.01 | E19: Removal of foreign body from spinal canal | F19: =VLOOKUP($D19,proc!$A:$D,3,FALSE) -> 5 | G19: =VLOOKUP($D19,proc!$A:$D,4,FALSE) -> 0 | H19: Moderate Spinal Proc. | J19: =VLOOKUP($D19,'prosedur-2025'!$A:$H,3,FALSE) -> 12 | K19: =VLOOKUP($D19,'prosedur-2025'!$A:$H,4,FALSE) -> 68030011 | L19: =VLOOKUP($D19,'prosedur-2025'!$A:$H,5,FALSE) -> 37169810 | M19: =VLOOKUP($D19,'prosedur-2025'!$A:$H,6,FALSE) -> 47495894 | N19: =VLOOKUP($D19,'prosedur-2025'!$A:$H,7,FALSE) -> 86573446 | O19: =VLOOKUP($D19,'prosedur-2025'!$A:$H,8,FALSE) -> 91434374 | P19: =J19*K19 -> 816360130
A20: PDC | B20: P11AD | C20: Complex Spinal Procedures | D20: 03.02 | E20: Reopening of laminectomy site | F20: =VLOOKUP($D20,proc!$A:$D,3,FALSE) -> 5 | G20: =VLOOKUP($D20,proc!$A:$D,4,FALSE) -> 0 | H20: Moderate Spinal Proc. | J20: =VLOOKUP($D20,'prosedur-2025'!$A:$H,3,FALSE) -> 226 | K20: =VLOOKUP($D20,'prosedur-2025'!$A:$H,4,FALSE) -> 58748393 | L20: =VLOOKUP($D20,'prosedur-2025'!$A:$H,5,FALSE) -> 27898024 | M20: =VLOOKUP($D20,'prosedur-2025'!$A:$H,6,FALSE) -> 46204400 | N20: =VLOOKUP($D20,'prosedur-2025'!$A:$H,7,FALSE) -> 74596310 | O20: =VLOOKUP($D20,'prosedur-2025'!$A:$H,8,FALSE) -> 122337966 | P20: =J20*K20 -> 13277136710
A21: PDC | B21: P11AD | C21: Complex Spinal Procedures | D21: 03.09 | E21: Other exploration and decompression of spinal canal | F21: =VLOOKUP($D21,proc!$A:$D,3,FALSE) -> 5 | G21: =VLOOKUP($D21,proc!$A:$D,4,FALSE) -> 0 | H21: Moderate Spinal Proc. | J21: =VLOOKUP($D21,'prosedur-2025'!$A:$H,3,FALSE) -> 9293 | K21: =VLOOKUP($D21,'prosedur-2025'!$A:$H,4,FALSE) -> 59760268 | L21: =VLOOKUP($D21,'prosedur-2025'!$A:$H,5,FALSE) -> 35810933 | M21: =VLOOKUP($D21,'prosedur-2025'!$A:$H,6,FALSE) -> 51791394 | N21: =VLOOKUP($D21,'prosedur-2025'!$A:$H,7,FALSE) -> 72016486 | O21: =VLOOKUP($D21,'prosedur-2025'!$A:$H,8,FALSE) -> 102710378 | P21: =J21*K21 -> 555352166212
A22: PDC | B22: P11AD | C22: Complex Spinal Procedures | D22: 03.21 | E22: Percutaneous chordotomy | F22: =VLOOKUP($D22,proc!$A:$D,3,FALSE) -> 4 | G22: =VLOOKUP($D22,proc!$A:$D,4,FALSE) -> 0 | H22: Moderate Spinal Proc. | J22: =VLOOKUP($D22,'prosedur-2025'!$A:$H,3,FALSE) -> 2 | K22: =VLOOKUP($D22,'prosedur-2025'!$A:$H,4,FALSE) -> 62128059 | L22: =VLOOKUP($D22,'prosedur-2025'!$A:$H,5,FALSE) -> 10275818 | M22: =VLOOKUP($D22,'prosedur-2025'!$A:$H,6,FALSE) -> 10275818 | N22: =VLOOKUP($D22,'prosedur-2025'!$A:$H,7,FALSE) -> 113980300 | O22: =VLOOKUP($D22,'prosedur-2025'!$A:$H,8,FALSE) -> 113980300 | P22: =J22*K22 -> 124256118
A23: PDC | B23: P11AD | C23: Complex Spinal Procedures | D23: 03.29 | E23: Other chordotomy | F23: =VLOOKUP($D23,proc!$A:$D,3,FALSE) -> 4 | G23: =VLOOKUP($D23,proc!$A:$D,4,FALSE) -> 0 | H23: Moderate Spinal Proc. | J23: =VLOOKUP($D23,'prosedur-2025'!$A:$H,3,FALSE) -> 14 | K23: =VLOOKUP($D23,'prosedur-2025'!$A:$H,4,FALSE) -> 56094480 | L23: =VLOOKUP($D23,'prosedur-2025'!$A:$H,5,FALSE) -> 17227265 | M23: =VLOOKUP($D23,'prosedur-2025'!$A:$H,6,FALSE) -> 58180620 | N23: =VLOOKUP($D23,'prosedur-2025'!$A:$H,7,FALSE) -> 88350158 | O23: =VLOOKUP($D23,'prosedur-2025'!$A:$H,8,FALSE) -> 97786657 | P23: =J23*K23 -> 785322726
A24: PDC | B24: P11AD | C24: Complex Spinal Procedures | D24: 03.4 | E24: Excision or destruction of lesion of spinal cord or spinal meninges | F24: =VLOOKUP($D24,proc!$A:$D,3,FALSE) -> 6 | G24: =VLOOKUP($D24,proc!$A:$D,4,FALSE) -> 0 | H24: Complex Spinal Proc. | J24: =VLOOKUP($D24,'prosedur-2025'!$A:$H,3,FALSE) -> 969 | K24: =VLOOKUP($D24,'prosedur-2025'!$A:$H,4,FALSE) -> 80259541 | L24: =VLOOKUP($D24,'prosedur-2025'!$A:$H,5,FALSE) -> 37570498 | M24: =VLOOKUP($D24,'prosedur-2025'!$A:$H,6,FALSE) -> 67611921 | N24: =VLOOKUP($D24,'prosedur-2025'!$A:$H,7,FALSE) -> 98550892 | O24: =VLOOKUP($D24,'prosedur-2025'!$A:$H,8,FALSE) -> 159266167 | P24: =J24*K24 -> 77771495627
A25: PDC | B25: P11AD | C25: Complex Spinal Procedures | D25: 03.51 | E25: Repair of spinal meningocele | F25: =VLOOKUP($D25,proc!$A:$D,3,FALSE) -> 5 | G25: =VLOOKUP($D25,proc!$A:$D,4,FALSE) -> 0 | H25: Moderate Spinal Proc. | J25: =VLOOKUP($D25,'prosedur-2025'!$A:$H,3,FALSE) -> 82 | K25: =VLOOKUP($D25,'prosedur-2025'!$A:$H,4,FALSE) -> 68166626 | L25: =VLOOKUP($D25,'prosedur-2025'!$A:$H,5,FALSE) -> 32504489 | M25: =VLOOKUP($D25,'prosedur-2025'!$A:$H,6,FALSE) -> 57467984 | N25: =VLOOKUP($D25,'prosedur-2025'!$A:$H,7,FALSE) -> 89998640 | O25: =VLOOKUP($D25,'prosedur-2025'!$A:$H,8,FALSE) -> 119390219 | P25: =J25*K25 -> 5589663365
A26: PDC | B26: P11AD | C26: Complex Spinal Procedures | D26: 03.52 | E26: Repair of spinal myelomeningocele | F26: =VLOOKUP($D26,proc!$A:$D,3,FALSE) -> 5 | G26: =VLOOKUP($D26,proc!$A:$D,4,FALSE) -> 0 | H26: Complex Spinal Proc. | J26: =VLOOKUP($D26,'prosedur-2025'!$A:$H,3,FALSE) -> 101 | K26: =VLOOKUP($D26,'prosedur-2025'!$A:$H,4,FALSE) -> 68653256 | L26: =VLOOKUP($D26,'prosedur-2025'!$A:$H,5,FALSE) -> 32601013 | M26: =VLOOKUP($D26,'prosedur-2025'!$A:$H,6,FALSE) -> 50170854 | N26: =VLOOKUP($D26,'prosedur-2025'!$A:$H,7,FALSE) -> 82461979 | O26: =VLOOKUP($D26,'prosedur-2025'!$A:$H,8,FALSE) -> 143505352 | P26: =J26*K26 -> 6933978859
A27: PDC | B27: P11AD | C27: Complex Spinal Procedures | D27: 03.53 | E27: Repair of vertebral fracture | F27: =VLOOKUP($D27,proc!$A:$D,3,FALSE) -> 5 | G27: =VLOOKUP($D27,proc!$A:$D,4,FALSE) -> 0 | H27: Moderate Spinal Proc. | J27: =VLOOKUP($D27,'prosedur-2025'!$A:$H,3,FALSE) -> 109 | K27: =VLOOKUP($D27,'prosedur-2025'!$A:$H,4,FALSE) -> 74716957 | L27: =VLOOKUP($D27,'prosedur-2025'!$A:$H,5,FALSE) -> 52512103 | M27: =VLOOKUP($D27,'prosedur-2025'!$A:$H,6,FALSE) -> 71569867 | N27: =VLOOKUP($D27,'prosedur-2025'!$A:$H,7,FALSE) -> 93427650 | O27: =VLOOKUP($D27,'prosedur-2025'!$A:$H,8,FALSE) -> 133643976 | P27: =J27*K27 -> 8144148286
... A30: PDC | B30: P11AD | C30: Complex Spinal Procedures | D30: 03.71 | E30: Spinal subarachnoid-peritoneal shunt | F30: =VLOOKUP($D30,proc!$A:$D,3,FALSE) -> 4 | G30: =VLOOKUP($D30,proc!$A:$D,4,FALSE) -> 0 | H30: Moderate Spinal Proc. | J30: =VLOOKUP($D30,'prosedur-2025'!$A:$H,3,FALSE) -> 11 | K30: =VLOOKUP($D30,'prosedur-2025'!$A:$H,4,FALSE) -> 61719059 | L30: =VLOOKUP($D30,'prosedur-2025'!$A:$H,5,FALSE) -> 30268917 | M30: =VLOOKUP($D30,'prosedur-2025'!$A:$H,6,FALSE) -> 49767972 | N30: =VLOOKUP($D30,'prosedur-2025'!$A:$H,7,FALSE) -> 82947747 | O30: =VLOOKUP($D30,'prosedur-2025'!$A:$H,8,FALSE) -> 92224400 | P30: =J30*K30 -> 678909647
A31: PDC | B31: P11AD | C31: Complex Spinal Procedures | D31: 03.72 | E31: Spinal subarachnoid-ureteral shunt | F31: =VLOOKUP($D31,proc!$A:$D,3,FALSE) -> 4 | G31: =VLOOKUP($D31,proc!$A:$D,4,FALSE) -> 0 | H31: Moderate Spinal Proc.
A32: PDC | B32: P11AD | C32: Complex Spinal Procedures | D32: 03.79 | E32: Other shunt of spinal theca | F32: =VLOOKUP($D32,proc!$A:$D,3,FALSE) -> 4 | G32: =VLOOKUP($D32,proc!$A:$D,4,FALSE) -> 0 | H32: Moderate Spinal Proc. | J32: =VLOOKUP($D32,'prosedur-2025'!$A:$H,3,FALSE) -> 28 | K32: =VLOOKUP($D32,'prosedur-2025'!$A:$H,4,FALSE) -> 86356199 | L32: =VLOOKUP($D32,'prosedur-2025'!$A:$H,5,FALSE) -> 50049275 | M32: =VLOOKUP($D32,'prosedur-2025'!$A:$H,6,FALSE) -> 87553186 | N32: =VLOOKUP($D32,'prosedur-2025'!$A:$H,7,FALSE) -> 118772842 | O32: =VLOOKUP($D32,'prosedur-2025'!$A:$H,8,FALSE) -> 144357842 | P32: =J32*K32 -> 2417973559
A33: PDC | B33: P11AD | C33: Complex Spinal Procedures | D33: 03.93 | E33: Implantation or replacement of spinal neurostimulator lead(s) | F33: =VLOOKUP($D33,proc!$A:$D,3,FALSE) -> 2 | G33: =VLOOKUP($D33,proc!$A:$D,4,FALSE) -> 0 | H33: Neuromodulation | J33: =VLOOKUP($D33,'prosedur-2025'!$A:$H,3,FALSE) -> 4 | K33: =VLOOKUP($D33,'prosedur-2025'!$A:$H,4,FALSE) -> 62796968 | L33: =VLOOKUP($D33,'prosedur-2025'!$A:$H,5,FALSE) -> 21537047 | M33: =VLOOKUP($D33,'prosedur-2025'!$A:$H,6,FALSE) -> 58677511 | N33: =VLOOKUP($D33,'prosedur-2025'!$A:$H,7,FALSE) -> 72113063 | O33: =VLOOKUP($D33,'prosedur-2025'!$A:$H,8,FALSE) -> 98860250 | P33: =J33*K33 -> 251187871
A34: PDC | B34: P11AD | C34: Complex Spinal Procedures | D34: 03.97 | E34: Revision of spinal thecal shunt | F34: =VLOOKUP($D34,proc!$A:$D,3,FALSE) -> 4 | G34: =VLOOKUP($D34,proc!$A:$D,4,FALSE) -> 0 | H34: Moderate Spinal Proc. | J34: =VLOOKUP($D34,'prosedur-2025'!$A:$H,3,FALSE) -> 4 | K34: =VLOOKUP($D34,'prosedur-2025'!$A:$H,4,FALSE) -> 37675131 | L34: =VLOOKUP($D34,'prosedur-2025'!$A:$H,5,FALSE) -> 6034823 | M34: =VLOOKUP($D34,'prosedur-2025'!$A:$H,6,FALSE) -> 6176764 | N34: =VLOOKUP($D34,'prosedur-2025'!$A:$H,7,FALSE) -> 23281087 | O34: =VLOOKUP($D34,'prosedur-2025'!$A:$H,8,FALSE) -> 115207850 | P34: =J34*K34 -> 150700524
A35: PDC | B35: P11AD | C35: Complex Spinal Procedures | D35: 03.99 | E35: Other operations on spinal cord and spinal canal structures | F35: =VLOOKUP($D35,proc!$A:$D,3,FALSE) -> 3 | G35: =VLOOKUP($D35,proc!$A:$D,4,FALSE) -> 0 | H35: Complex Spinal Proc. | J35: =VLOOKUP($D35,'prosedur-2025'!$A:$H,3,FALSE) -> 43 | K35: =VLOOKUP($D35,'prosedur-2025'!$A:$H,4,FALSE) -> 67769438 | L35: =VLOOKUP($D35,'prosedur-2025'!$A:$H,5,FALSE) -> 28286512 | M35: =VLOOKUP($D35,'prosedur-2025'!$A:$H,6,FALSE) -> 54070788 | N35: =VLOOKUP($D35,'prosedur-2025'!$A:$H,7,FALSE) -> 90470150 | O35: =VLOOKUP($D35,'prosedur-2025'!$A:$H,8,FALSE) -> 121648571 | P35: =J35*K35 -> 2914085816
A36: PDC | B36: P11AD | C36: Complex Spinal Procedures | D36: 77.81 | E36: Other partial ostectomy, scapula, clavicle, and thorax [ribs and sternum] | F36: =VLOOKUP($D36,proc!$A:$D,3,FALSE) -> 3 | G36: =VLOOKUP($D36,proc!$A:$D,4,FALSE) -> 0 | H36: Moderate Spinal Proc. | J36: =VLOOKUP($D36,'prosedur-2025'!$A:$H,3,FALSE) -> 121 | K36: =VLOOKUP($D36,'prosedur-2025'!$A:$H,4,FALSE) -> 38161526 | L36: =VLOOKUP($D36,'prosedur-2025'!$A:$H,5,FALSE) -> 8518840 | M36: =VLOOKUP($D36,'prosedur-2025'!$A:$H,6,FALSE) -> 15333076 | N36: =VLOOKUP($D36,'prosedur-2025'!$A:$H,7,FALSE) -> 32317948 | O36: =VLOOKUP($D36,'prosedur-2025'!$A:$H,8,FALSE) -> 102633976 | P36: =J36*K36 -> 4617544641
A37: PDC | B37: P11AD | C37: Complex Spinal Procedures | D37: 77.91 | E37: Total ostectomy, scapula, clavicle, and thorax [ribs and sternum] | F37: =VLOOKUP($D37,proc!$A:$D,3,FALSE) -> 5 | G37: =VLOOKUP($D37,proc!$A:$D,4,FALSE) -> 0 | H37: Moderate Spinal Proc. | J37: =VLOOKUP($D37,'prosedur-2025'!$A:$H,3,FALSE) -> 61 | K37: =VLOOKUP($D37,'prosedur-2025'!$A:$H,4,FALSE) -> 48177048 | L37: =VLOOKUP($D37,'prosedur-2025'!$A:$H,5,FALSE) -> 15263017 | M37: =VLOOKUP($D37,'prosedur-2025'!$A:$H,6,FALSE) -> 30053842 | N37: =VLOOKUP($D37,'prosedur-2025'!$A:$H,7,FALSE) -> 63933300 | O37: =VLOOKUP($D37,'prosedur-2025'!$A:$H,8,FALSE) -> 112482408 | P37: =J37*K37 -> 2938799910
A38: PDC | B38: P11AD | C38: Complex Spinal Procedures | D38: 80.55 | E38: Microdissectomy (endoscopic/microscopic) (IM) | F38: =VLOOKUP($D38,proc!$A:$D,3,FALSE) -> 4 | G38: =VLOOKUP($D38,proc!$A:$D,4,FALSE) -> 1 | H38: Moderate Spinal Proc.
A39: PDC | B39: P11AD | C39: Complex Spinal Procedures | D39: 81.00 | E39: Spinal fusion, not otherwise specified | F39: =VLOOKUP($D39,proc!$A:$D,3,FALSE) -> 5 | G39: =VLOOKUP($D39,proc!$A:$D,4,FALSE) -> 0 | H39: Complex Spinal Proc. | J39: =VLOOKUP($D39,'prosedur-2025'!$A:$H,3,FALSE) -> 1528 | K39: =VLOOKUP($D39,'prosedur-2025'!$A:$H,4,FALSE) -> 65674909 | L39: =VLOOKUP($D39,'prosedur-2025'!$A:$H,5,FALSE) -> 49936194 | M39: =VLOOKUP($D39,'prosedur-2025'!$A:$H,6,FALSE) -> 61234300 | N39: =VLOOKUP($D39,'prosedur-2025'!$A:$H,7,FALSE) -> 74515004 | O39: =VLOOKUP($D39,'prosedur-2025'!$A:$H,8,FALSE) -> 97919911 | P39: =J39*K39 -> 100351260453
A40: PDC | B40: P11AD | C40: Complex Spinal Procedures | D40: 81.01 | E40: Atlas-axis spinal fusion | F40: =VLOOKUP($D40,proc!$A:$D,3,FALSE) -> 6 | G40: =VLOOKUP($D40,proc!$A:$D,4,FALSE) -> 0 | H40: Complex Spinal Proc. | J40: =VLOOKUP($D40,'prosedur-2025'!$A:$H,3,FALSE) -> 27 | K40: =VLOOKUP($D40,'prosedur-2025'!$A:$H,4,FALSE) -> 1.2467283e+08 | L40: =VLOOKUP($D40,'prosedur-2025'!$A:$H,5,FALSE) -> 52639588 | M40: =VLOOKUP($D40,'prosedur-2025'!$A:$H,6,FALSE) -> 87551311 | N40: =VLOOKUP($D40,'prosedur-2025'!$A:$H,7,FALSE) -> 115964551 | O40: =VLOOKUP($D40,'prosedur-2025'!$A:$H,8,FALSE) -> 208639207 | P40: =J40*K40 -> 3366166364
A41: PDC | B41: P11AD | C41: Complex Spinal Procedures | D41: 81.02 | E41: Other cervical fusion of the anterior column, anterior technique | F41: =VLOOKUP($D41,proc!$A:$D,3,FALSE) -> 5 | G41: =VLOOKUP($D41,proc!$A:$D,4,FALSE) -> 0 | H41: Complex Spinal Proc. | J41: =VLOOKUP($D41,'prosedur-2025'!$A:$H,3,FALSE) -> 1124 | K41: =VLOOKUP($D41,'prosedur-2025'!$A:$H,4,FALSE) -> 81393964 | L41: =VLOOKUP($D41,'prosedur-2025'!$A:$H,5,FALSE) -> 49774876 | M41: =VLOOKUP($D41,'prosedur-2025'!$A:$H,6,FALSE) -> 68684800 | N41: =VLOOKUP($D41,'prosedur-2025'!$A:$H,7,FALSE) -> 97992005 | O41: =VLOOKUP($D41,'prosedur-2025'!$A:$H,8,FALSE) -> 141735725 | P41: =J41*K41 -> 91486815900
A42: PDC | B42: P11AD | C42: Complex Spinal Procedures | D42: 81.03 | E42: Other cervical fusion of the posterior column, posterior technique | F42: =VLOOKUP($D42,proc!$A:$D,3,FALSE) -> 5 | G42: =VLOOKUP($D42,proc!$A:$D,4,FALSE) -> 0 | H42: Complex Spinal Proc. | J42: =VLOOKUP($D42,'prosedur-2025'!$A:$H,3,FALSE) -> 875 | K42: =VLOOKUP($D42,'prosedur-2025'!$A:$H,4,FALSE) -> 94529035 | L42: =VLOOKUP($D42,'prosedur-2025'!$A:$H,5,FALSE) -> 56619127 | M42: =VLOOKUP($D42,'prosedur-2025'!$A:$H,6,FALSE) -> 78073992 | N42: =VLOOKUP($D42,'prosedur-2025'!$A:$H,7,FALSE) -> 110993428 | O42: =VLOOKUP($D42,'prosedur-2025'!$A:$H,8,FALSE) -> 160154433 | P42: =J42*K42 -> 82712905872
...

Sheet Sheet8
A1: ICD | B1: Deskripsi ICD | C1: PDC
A2: A06.6 | B2: Amoebic brain abscess | C2: PDC D11AA Nervous system infection
A3: A17.0 | B3: Tuberculous meningitis | C3: PDC D11AA Nervous system infection
A4: A17.1 | B4: Meningeal tuberculoma | C4: PDC D11AA Nervous system infection
A5: A17.8 | B5: Other tuberculosis of nervous system | C5: PDC D11AA Nervous system infection
A6: A17.9 | B6: Tuberculosis of nervous system unspecified | C6: PDC D11AA Nervous system infection
A7: A32.1 | B7: Listerial meningitis and meningoencephalitis | C7: PDC D11AA Nervous system infection
A8: A39.0 | B8: Meningococcal meningitis | C8: PDC D11AA Nervous system infection
A9: A50.4 | B9: Late congenital neurosyphilis [juvenile neurosyphilis] | C9: PDC D11AA Nervous system infection
A10: A52.1 | B10: Symptomatic neurosyphilis | C10: PDC D11AA Nervous system infection
A11: A52.2 | B11: Asymptomatic neurosyphilis | C11: PDC D11AA Nervous system infection
A12: A52.3 | B12: Neurosyphilis, unspecified | C12: PDC D11AA Nervous system infection
... A796: Z90.0 | B796: Acquired absence of part of head and neck | C796: PDC D11AV Gangguan Penyakit Sistem Persarafan Lain-lain
A797: ="00.62" -> 00.62 | B797: Percutaneous angioplasty or atherectomy of intracranial vessel(s) | C797: PDC P11AA Endovascular Procedures for Neurologic Diseases
A798: 38.52 | B798: Ligation and stripping of varicose veins, other vessels of head and neck | C798: PDC P11AA Endovascular Procedures for Neurologic Diseases
A799: 38.7 | B799: Interruption vena cava | C799: PDC P11AA Endovascular Procedures for Neurologic Diseases
A800: 38.82 | B800: Other surgical occlusion of vessels, other vessels of head and neck | C800: PDC P11AA Endovascular Procedures for Neurologic Diseases
A801: 39.72 | B801: Endovascular embolization or occlusion of head and neck vessels | C801: PDC P11AA Endovascular Procedures for Neurologic Diseases
A802: 39.74 | B802: Endovascular removal of obstruction from head and neck vessel(s) | C802: PDC P11AA Endovascular Procedures for Neurologic Diseases
A803: 39.75 | B803: Endovascular embolization or occlusion of vessel(s) of head or neck using bare coils | C803: PDC P11AA Endovascular Procedures for Neurologic Diseases
A804: 39.76 | B804: Endovascular embolization or occlusion of vessel(s) of head or neck using bioactive coils | C804: PDC P11AA Endovascular Procedures for Neurologic Diseases
A805: 39.81 | B805: Implantation or replacement of carotid sinus stimulation device, total system (IM) | C805: PDC P11AA Endovascular Procedures for Neurologic Diseases
A806: 39.82 | B806: Implantation or replacement of carotid sinus stimulation lead(s) only (IM) | C806: PDC P11AA Endovascular Procedures for Neurologic Diseases
A807: 39.83 | B807: Implantation or replacement of carotid sinus stimulation pulse generator only (IM) | C807: PDC P11AA Endovascular Procedures for Neurologic Diseases
A808: 39.84 | B808: Revision of carotid sinus stimulation lead(s) only (IM) | C808: PDC P11AA Endovascular Procedures for Neurologic Diseases
A809: 39.85 | B809: Revision of carotid sinus stimulation pulse generator (IM) | C809: PDC P11AA Endovascular Procedures for Neurologic Diseases
... A813: 39.89 | B813: Other operations on carotid body, carotid sinus and other vascular bodies (IM) | C813: PDC P11AA Endovascular Procedures for Neurologic Diseases
A814: ="03.4" -> 03.4 | B814: Excision or destruction of lesion of spinal cord or spinal meninges | C814: PDC P11AB Complex Spinal Procedures
A815: ="03.52" -> 03.52 | B815: Repair of spinal myelomeningocele | C815: PDC P11AB Complex Spinal Procedures
A816: ="03.99" -> 03.99 | B816: Other operations on spinal cord and spinal canal structures | C816: PDC P11AB Complex Spinal Procedures
A817: 81 | B817: Spinal fusion, not otherwise specified | C817: PDC P11AB Complex Spinal Procedures
A818: 81.01 | B818: Atlas-axis spinal fusion | C818: PDC P11AB Complex Spinal Procedures
A819: 81.02 | B819: Other cervical fusion of the anterior column, anterior technique | C819: PDC P11AB Complex Spinal Procedures
A820: 81.03 | B820: Other cervical fusion of the posterior column, posterior technique | C820: PDC P11AB Complex Spinal Procedures
A821: 81.04 | B821: Dorsal and dorsolumbar fusion of the anterior column, anterior technique | C821: PDC P11AB Complex Spinal Procedures
A822: 81.05 | B822: Dorsal and dorsolumbar fusion of the posterior column, posterior technique | C822: PDC P11AB Complex Spinal Procedures
A823: 81.06 | B823: Lumbar and lumbosacral fusion of the anterior column, anterior technique | C823: PDC P11AB Complex Spinal Procedures
A824: 81.07 | B824: Lumbar and lumbosacral fusion of the posterior column, posterior technique | C824: PDC P11AB Complex Spinal Procedures
A825: 81.08 | B825: Lumbar and lumbosacral fusion of the anterior column, posterior technique | C825: PDC P11AB Complex Spinal Procedures
A826: 81.3 | B826: Refusion of spine, not otherwise specified | C826: PDC P11AB Complex Spinal Procedures
...

Sheet ranap clusters (ICD 9)
A1: Cluster Type | B1: Cluster Code | C1: Cluster Description | D1: ICD-9-CM Code | E1: ICD-9-CM Description | F1: Grade | G1: IM | H1: ICD-9-CM no dot | I1: New Cluster Description | J1: New Cluster Code | K1: jumlah kasus | L1: mean_billing | M1: p25 | N1: p50 | O1: p75 | P1: p90 | Q1: total | R1: Keterangan | S1: Action | T1: ICD-9 Code | U1: ICD 10 | V1: Deskripsi ICD 10 | W1: code | X1: mdc | Y1: pdc | Z1: ptd | AA1: description | AB1: catatan upload | AC1: ax | AD1: code | AE1: cl
A2: PDC | B2: P11AC | C2: Endovascular Procedures for Neurologic Diseases | D2: 00.62 | E2: Percutaneous angioplasty or atherectomy of intracranial vessel(s) | F2: =VLOOKUP($D2,proc!$A:$D,3,FALSE) -> 3 | G2: =VLOOKUP($D2,proc!$A:$D,4,FALSE) -> 0 | H2: 0062 | I2: #N/A | J2: #N/A | K2: =VLOOKUP($D2,'prosedur-2025'!$A:$H,3,FALSE) -> 120 | L2: =VLOOKUP($D2,'prosedur-2025'!$A:$H,4,FALSE) -> 78497963 | M2: =VLOOKUP($D2,'prosedur-2025'!$A:$H,5,FALSE) -> 31029390 | N2: =VLOOKUP($D2,'prosedur-2025'!$A:$H,6,FALSE) -> 49040723 | O2: =VLOOKUP($D2,'prosedur-2025'!$A:$H,7,FALSE) -> 88993193 | P2: =VLOOKUP($D2,'prosedur-2025'!$A:$H,8,FALSE) -> 153022000 | Q2: =K2*L2 -> 9419755502 | R2: sudah ada rumah baru PTA Cerebral (CK) | S2: drop
A3: PDC | B3: P11AC | C3: Endovascular Procedures for Neurologic Diseases | D3: 38.52 | E3: Ligation and stripping of varicose veins, other vessels of head and neck | F3: =VLOOKUP($D3,proc!$A:$D,3,FALSE) -> 0 | G3: =VLOOKUP($D3,proc!$A:$D,4,FALSE) -> 0 | H3: =SUBSTITUTE(D3,".","") -> 3852 | I3: Endovascular Proc. for Neurologic Diseases | J3: =VLOOKUP(H3,'upload c51prpdc'!A:C,3,FALSE) -> P11AA | K3: =VLOOKUP($D3,'prosedur-2025'!$A:$H,3,FALSE) -> 33 | L3: =VLOOKUP($D3,'prosedur-2025'!$A:$H,4,FALSE) -> 21821658 | M3: =VLOOKUP($D3,'prosedur-2025'!$A:$H,5,FALSE) -> 7330331 | N3: =VLOOKUP($D3,'prosedur-2025'!$A:$H,6,FALSE) -> 13625695 | O3: =VLOOKUP($D3,'prosedur-2025'!$A:$H,7,FALSE) -> 22771045 | P3: =VLOOKUP($D3,'prosedur-2025'!$A:$H,8,FALSE) -> 55892400 | Q3: =K3*L3 -> 720114702 | T3: =TEXT(VALUE(D3),"00.00") -> 38.52 | W3: =H3 -> 3852 | X3: 11 | Y3: =J3 -> P11AA | Z3: 1 | AA3: =I3 -> Endovascular Proc. for Neurologic Diseases
A4: PDC | B4: P11AC | C4: Endovascular Procedures for Neurologic Diseases | D4: 38.7 | E4: Interruption vena cava | F4: =VLOOKUP($D4,proc!$A:$D,3,FALSE) -> 5 | G4: =VLOOKUP($D4,proc!$A:$D,4,FALSE) -> 0 | H4: =SUBSTITUTE(D4,".","") -> 387 | I4: Endovascular Proc. for Neurologic Diseases | J4: =VLOOKUP(H4,'upload c51prpdc'!A:C,3,FALSE) -> P11AA | K4: =VLOOKUP($D4,'prosedur-2025'!$A:$H,3,FALSE) -> 121 | L4: =VLOOKUP($D4,'prosedur-2025'!$A:$H,4,FALSE) -> 67670327 | M4: =VLOOKUP($D4,'prosedur-2025'!$A:$H,5,FALSE) -> 29852859 | N4: =VLOOKUP($D4,'prosedur-2025'!$A:$H,6,FALSE) -> 58105112 | O4: =VLOOKUP($D4,'prosedur-2025'!$A:$H,7,FALSE) -> 92598541 | P4: =VLOOKUP($D4,'prosedur-2025'!$A:$H,8,FALSE) -> 135912123 | Q4: =K4*L4 -> 8188109584 | T4: =TEXT(VALUE(D4),"00.00") -> 38.70 | W4: =H4 -> 387 | X4: 11 | Y4: =J4 -> P11AA | Z4: 1 | AA4: =I4 -> Endovascular Proc. for Neurologic Diseases
A5: PDC | B5: P11AC | C5: Endovascular Procedures for Neurologic Diseases | D5: 38.82 | E5: Other surgical occlusion of vessels, other vessels of head and neck | F5: =VLOOKUP($D5,proc!$A:$D,3,FALSE) -> 4 | G5: =VLOOKUP($D5,proc!$A:$D,4,FALSE) -> 0 | H5: =SUBSTITUTE(D5,".","") -> 3882 | I5: Endovascular Proc. for Neurologic Diseases | J5: =VLOOKUP(H5,'upload c51prpdc'!A:C,3,FALSE) -> P11AA | K5: =VLOOKUP($D5,'prosedur-2025'!$A:$H,3,FALSE) -> 434 | L5: =VLOOKUP($D5,'prosedur-2025'!$A:$H,4,FALSE) -> 48032893 | M5: =VLOOKUP($D5,'prosedur-2025'!$A:$H,5,FALSE) -> 10435277 | N5: =VLOOKUP($D5,'prosedur-2025'!$A:$H,6,FALSE) -> 22179491 | O5: =VLOOKUP($D5,'prosedur-2025'!$A:$H,7,FALSE) -> 61098522 | P5: =VLOOKUP($D5,'prosedur-2025'!$A:$H,8,FALSE) -> 123946351 | Q5: =K5*L5 -> 20846275429 | T5: =TEXT(VALUE(D5),"00.00") -> 38.82 | W5: =H5 -> 3882 | X5: 11 | Y5: =J5 -> P11AA | Z5: 1 | AA5: =I5 -> Endovascular Proc. for Neurologic Diseases
A6: PDC | B6: P11AC | C6: Endovascular Procedures for Neurologic Diseases | D6: 39.72 | E6: Endovascular embolization or occlusion of head and neck vessels | F6: =VLOOKUP($D6,proc!$A:$D,3,FALSE) -> 6 | G6: =VLOOKUP($D6,proc!$A:$D,4,FALSE) -> 0 | H6: =SUBSTITUTE(D6,".","") -> 3972 | I6: Endovascular Proc. for Neurologic Diseases | J6: =VLOOKUP(H6,'upload c51prpdc'!A:C,3,FALSE) -> P11AA | K6: =VLOOKUP($D6,'prosedur-2025'!$A:$H,3,FALSE) -> 339 | L6: =VLOOKUP($D6,'prosedur-2025'!$A:$H,4,FALSE) -> 77422054 | M6: =VLOOKUP($D6,'prosedur-2025'!$A:$H,5,FALSE) -> 34528674 | N6: =VLOOKUP($D6,'prosedur-2025'!$A:$H,6,FALSE) -> 59125877 | O6: =VLOOKUP($D6,'prosedur-2025'!$A:$H,7,FALSE) -> 99036851 | P6: =VLOOKUP($D6,'prosedur-2025'!$A:$H,8,FALSE) -> 162366954 | Q6: =K6*L6 -> 26246076412 | T6: =TEXT(VALUE(D6),"00.00") -> 39.72 | W6: =H6 -> 3972 | X6: 11 | Y6: =J6 -> P11AA | Z6: 1 | AA6: =I6 -> Endovascular Proc. for Neurologic Diseases
A7: PDC | D7: 39.720 | E7: Endovascular repair or occlusion of head and neck vessels with detachable balloon (IM) | F7: 6 | G7: 1 | H7: =SUBSTITUTE(D7,".","") -> 39720 | I7: Endovascular Proc. for Neurologic Diseases | J7: P11AA | W7: =H7 -> 39720 | X7: 11 | Y7: =J7 -> P11AA | Z7: 1 | AA7: =I7 -> Endovascular Proc. for Neurologic Diseases
A8: PDC | B8: P11AC | C8: Endovascular Procedures for Neurologic Diseases | D8: 39.74 | E8: Endovascular removal of obstruction from head and neck vessel(s) | F8: =VLOOKUP($D8,proc!$A:$D,3,FALSE) -> 5 | G8: =VLOOKUP($D8,proc!$A:$D,4,FALSE) -> 0 | H8: =SUBSTITUTE(D8,".","") -> 3974 | I8: Endovascular Proc. for Neurologic Diseases | J8: =VLOOKUP(H8,'upload c51prpdc'!A:C,3,FALSE) -> P11AA | K8: =VLOOKUP($D8,'prosedur-2025'!$A:$H,3,FALSE) -> 412 | L8: =VLOOKUP($D8,'prosedur-2025'!$A:$H,4,FALSE) -> 1.1316846e+08 | M8: =VLOOKUP($D8,'prosedur-2025'!$A:$H,5,FALSE) -> 61273050 | N8: =VLOOKUP($D8,'prosedur-2025'!$A:$H,6,FALSE) -> 97611950 | O8: =VLOOKUP($D8,'prosedur-2025'!$A:$H,7,FALSE) -> 139420700 | P8: =VLOOKUP($D8,'prosedur-2025'!$A:$H,8,FALSE) -> 193880000 | Q8: =K8*L8 -> 46625405734 | T8: =TEXT(VALUE(D8),"00.00") -> 39.74 | W8: =H8 -> 3974 | X8: 11 | Y8: =J8 -> P11AA | Z8: 1 | AA8: =I8 -> Endovascular Proc. for Neurologic Diseases
A9: PDC | B9: P11AC | C9: Endovascular Procedures for Neurologic Diseases | D9: 39.75 | E9: Endovascular embolization or occlusion of vessel(s) of head or neck using bare coils | F9: =VLOOKUP($D9,proc!$A:$D,3,FALSE) -> 5 | G9: =VLOOKUP($D9,proc!$A:$D,4,FALSE) -> 0 | H9: =SUBSTITUTE(D9,".","") -> 3975 | I9: Endovascular Proc. for Neurologic Diseases | J9: =VLOOKUP(H9,'upload c51prpdc'!A:C,3,FALSE) -> P11AA | K9: =VLOOKUP($D9,'prosedur-2025'!$A:$H,3,FALSE) -> 820 | L9: =VLOOKUP($D9,'prosedur-2025'!$A:$H,4,FALSE) -> 1.2139781e+08 | M9: =VLOOKUP($D9,'prosedur-2025'!$A:$H,5,FALSE) -> 72539060 | N9: =VLOOKUP($D9,'prosedur-2025'!$A:$H,6,FALSE) -> 100933007 | O9: =VLOOKUP($D9,'prosedur-2025'!$A:$H,7,FALSE) -> 144954100 | P9: =VLOOKUP($D9,'prosedur-2025'!$A:$H,8,FALSE) -> 207161425 | Q9: =K9*L9 -> 99546207534 | T9: =TEXT(VALUE(D9),"00.00") -> 39.75 | W9: =H9 -> 3975 | X9: 11 | Y9: =J9 -> P11AA | Z9: 1 | AA9: =I9 -> Endovascular Proc. for Neurologic Diseases
A10: PDC | B10: P11AC | C10: Endovascular Procedures for Neurologic Diseases | D10: 39.76 | E10: Endovascular embolization or occlusion of vessel(s) of head or neck using bioactive coils | F10: =VLOOKUP($D10,proc!$A:$D,3,FALSE) -> 5 | G10: =VLOOKUP($D10,proc!$A:$D,4,FALSE) -> 0 | H10: =SUBSTITUTE(D10,".","") -> 3976 | I10: Endovascular Proc. for Neurologic Diseases | J10: =VLOOKUP(H10,'upload c51prpdc'!A:C,3,FALSE) -> P11AA | K10: =VLOOKUP($D10,'prosedur-2025'!$A:$H,3,FALSE) -> 25 | L10: =VLOOKUP($D10,'prosedur-2025'!$A:$H,4,FALSE) -> 73873294 | M10: =VLOOKUP($D10,'prosedur-2025'!$A:$H,5,FALSE) -> 46871484 | N10: =VLOOKUP($D10,'prosedur-2025'!$A:$H,6,FALSE) -> 62436689 | O10: =VLOOKUP($D10,'prosedur-2025'!$A:$H,7,FALSE) -> 95671460 | P10: =VLOOKUP($D10,'prosedur-2025'!$A:$H,8,FALSE) -> 147131046 | Q10: =K10*L10 -> 1846832339 | T10: =TEXT(VALUE(D10),"00.00") -> 39.76 | W10: =H10 -> 3976 | X10: 11 | Y10: =J10 -> P11AA | Z10: 1 | AA10: =I10 -> Endovascular Proc. for Neurologic Diseases
